Workbook

Sheet AGENTE 
E1: EMPRESA: | G1: GRUPO TORRES PATRIMONIAL | AC1: Horário de Trabalho Interno | AD1: 0.66666667 | AE1: 0.00069444444 | AF1: Urbana 2 | AG1: 0.75
AD2: 40 | AF2: Urbana | AG2: 0.74930556
E3: ENDEREÇO: | N3: CEP: | AC3: Ficha Individual - Art 74/3 CLT | AD3: 0 | AF3: Folga | AG3: 0
E4: BAIRRO: | N4: CIDADE: | P4: UF: | Q4: SP | AC4: Portaria Nº 3082 de 11/04/98
E5: CODIGO: 0000 | G5: NOME | L5: AGENTE DE ESCOLTA
AC6: MÊS | AD6: 9
E7: CARGO : VIGILANTE DE ESCOLTA ARMADA | U7: RODOVIÁRIO | V7: 38 | AC7: 44620
E8: DEPTO/ SETOR/ SEÇÃO: 0001/ 0002 / 0000 | U8: URBANO | V8: 38
A10: DATA | C10: DIA | D10: TIPO | E10: ENTRADA | J10: SAÍDA | K10: PERNOITE | L10: Horas Desconto | M10: T. H Corrida | N10: DIÁRIA | O10: AD. NOT. | Q10: ASS. FUNCIONÁRIO | AC10: OBSERVAÇÕES
D11: ESCOLTA | F11: SAÍDA | G11: ENTRADA | H11: SAÍDA | I11: ENTRADA | U11: SOMA AD. NOT | V11: RESULTADO ENTRADA | W11: REFERENCIA ENTRADA | X11: RESULTADO SAIDA | Y11: REFERENCIA SAIDA | Z11: CONDIÇÃO DE SOMA ENTRADA | AA11: CONDIÇÃO DE SOMA SAIDA | AB11: REFERENCIA HORAS EM NUMEROS | AE11: Q1 | AF11: =COUNTIF($N$12:$N$31,$AD$2) -> 0 | AG11: =SUM(N12:N31) -> 0
A12: 44645 | B12: 44185 | C12: =TEXT(A12,"ddd") -> qui | L12: =IFERROR((F12-E12)+(H12-G12)+(J12-I12)-K12,0) -> 0 | M12: =IFERROR(J12-E12,0) -> 0 | O12: =U12 -> 0 | U12: =V12+X12 -> 0 | V12: =IFERROR(W12-Z12,0) -> 0 | W12: =IF(AND(E12>=$AB$19,E12<=$AB$20),$AB$20,IF(AND(E12>=$AB$17,E12<=$AB$18),$AB$17,0)) -> 0 | X12: =IFERROR(AA12-Y12,0) -> 0 | Y12: =IF(AND(J12>=$AB$19,J12<=$AB$20),$AB$20,IF(AND(J12>=$AB$17,J12<=$AB$18),$AB$17,0)) -> 0 | Z12: =IF(AND($E12>=$AB$17,$E12<=$AB$18),$E12,IF(AND($E12>=$AB$19,$E12<=$AB$20),$E12,0)) -> 0 | AA12: =IF(AND($J12>=$AB$17,$J12<=$AB$18),$J12,IF(AND($J12>=$AB$19,$J12<=$AB$20),$J12,0)) -> 0 | AE12: Q2 | AF12: =COUNTIF($N$32:$N$42,$AD$2) -> 0 | AG12: =SUM(N32:N42) -> 0
A13: =A12+1 -> 44646 | B13: =B12+1 -> 44186 | C13: =TEXT(A13,"ddd") -> sex | L13: =IFERROR((F13-E13)+(H13-G13)+(J13-I13)-K13,0) -> 0 | M13: =IFERROR(J13-E13,0) -> 0 | O13: =U13 -> 0 | U13: =V13+X13 -> 0 | V13: =IFERROR(W13-Z13,0) -> 0 | W13: =IF(AND(E13>=$AB$19,E13<=$AB$20),$AB$20,IF(AND(E13>=$AB$17,E13<=$AB$18),$AB$17,0)) -> 0 | X13: =IFERROR(AA13-Y13,0) -> 0 | Y13: =IF(AND(J13>=$AB$19,J13<=$AB$20),$AB$20,IF(AND(J13>=$AB$17,J13<=$AB$18),$AB$17,0)) -> 0 | Z13: =IF(AND($E13>=$AB$17,$E13<=$AB$18),$E13,IF(AND($E13>=$AB$19,$E13<=$AB$20),$E13,0)) -> 0 | AA13: =IF(AND($J13>=$AB$17,$J13<=$AB$18),$J13,IF(AND($J13>=$AB$19,$J13<=$AB$20),$J13,0)) -> 0
A14: =A13+1 -> 44647 | B14: =B13+1 -> 44187 | C14: =TEXT(A14,"ddd") -> sáb | L14: =IFERROR((F14-E14)+(H14-G14)+(J14-I14)-K14,0) -> 0 | M14: =IFERROR(J14-E14,0) -> 0 | O14: =U14 -> 0 | U14: =V14+X14 -> 0 | V14: =IFERROR(W14-Z14,0) -> 0 | W14: =IF(AND(E14>=$AB$19,E14<=$AB$20),$AB$20,IF(AND(E14>=$AB$17,E14<=$AB$18),$AB$17,0)) -> 0 | X14: =IFERROR(AA14-Y14,0) -> 0 | Y14: =IF(AND(J14>=$AB$19,J14<=$AB$20),$AB$20,IF(AND(J14>=$AB$17,J14<=$AB$18),$AB$17,0)) -> 0 | Z14: =IF(AND($E14>=$AB$17,$E14<=$AB$18),$E14,IF(AND($E14>=$AB$19,$E14<=$AB$20),$E14,0)) -> 0 | AA14: =IF(AND($J14>=$AB$17,$J14<=$AB$18),$J14,IF(AND($J14>=$AB$19,$J14<=$AB$20),$J14,0)) -> 0
A15: =A14+1 -> 44648 | B15: =B14+1 -> 44188 | C15: =TEXT(A15,"ddd") -> dom | L15: =IFERROR((F15-E15)+(H15-G15)+(J15-I15)-K15,0) -> 0 | M15: =IFERROR(J15-E15,0) -> 0 | O15: =U15 -> 0 | U15: =V15+X15 -> 0 | V15: =IFERROR(W15-Z15,0) -> 0 | W15: =IF(AND(E15>=$AB$19,E15<=$AB$20),$AB$20,IF(AND(E15>=$AB$17,E15<=$AB$18),$AB$17,0)) -> 0 | X15: =IFERROR(AA15-Y15,0) -> 0 | Y15: =IF(AND(J15>=$AB$19,J15<=$AB$20),$AB$20,IF(AND(J15>=$AB$17,J15<=$AB$18),$AB$17,0)) -> 0 | Z15: =IF(AND($E15>=$AB$17,$E15<=$AB$18),$E15,IF(AND($E15>=$AB$19,$E15<=$AB$20),$E15,0)) -> 0 | AA15: =IF(AND($J15>=$AB$17,$J15<=$AB$18),$J15,IF(AND($J15>=$AB$19,$J15<=$AB$20),$J15,0)) -> 0
A16: =A15+1 -> 44649 | B16: =B15+1 -> 44189 | C16: =TEXT(A16,"ddd") -> seg | L16: =IFERROR((F16-E16)+(H16-G16)+(J16-I16)-K16,0) -> 0 | M16: =IFERROR(J16-E16,0) -> 0 | O16: =U16 -> 0 | U16: =V16+X16 -> 0 | V16: =IFERROR(W16-Z16,0) -> 0 | W16: =IF(AND(E16>=$AB$19,E16<=$AB$20),$AB$20,IF(AND(E16>=$AB$17,E16<=$AB$18),$AB$17,0)) -> 0 | X16: =IFERROR(AA16-Y16,0) -> 0 | Y16: =IF(AND(J16>=$AB$19,J16<=$AB$20),$AB$20,IF(AND(J16>=$AB$17,J16<=$AB$18),$AB$17,0)) -> 0 | Z16: =IF(AND($E16>=$AB$17,$E16<=$AB$18),$E16,IF(AND($E16>=$AB$19,$E16<=$AB$20),$E16,0)) -> 0 | AA16: =IF(AND($J16>=$AB$17,$J16<=$AB$18),$J16,IF(AND($J16>=$AB$19,$J16<=$AB$20),$J16,0)) -> 0
A17: =A16+1 -> 44650 | B17: =B16+1 -> 44190 | C17: =TEXT(A17,"ddd") -> ter | L17: =IFERROR((F17-E17)+(H17-G17)+(J17-I17)-K17,0) -> 0 | M17: =IFERROR(J17-E17,0) -> 0 | O17: =U17 -> 0 | U17: =V17+X17 -> 0 | V17: =IFERROR(W17-Z17,0) -> 0 | W17: =IF(AND(E17>=$AB$19,E17<=$AB$20),$AB$20,IF(AND(E17>=$AB$17,E17<=$AB$18),$AB$17,0)) -> 0 | X17: =IFERROR(AA17-Y17,0) -> 0 | Y17: =IF(AND(J17>=$AB$19,J17<=$AB$20),$AB$20,IF(AND(J17>=$AB$17,J17<=$AB$18),$AB$17,0)) -> 0 | Z17: =IF(AND($E17>=$AB$17,$E17<=$AB$18),$E17,IF(AND($E17>=$AB$19,$E17<=$AB$20),$E17,0)) -> 0 | AA17: =IF(AND($J17>=$AB$17,$J17<=$AB$18),$J17,IF(AND($J17>=$AB$19,$J17<=$AB$20),$J17,0)) -> 0 | AB17: 0.91666667
A18: =A17+1 -> 44651 | B18: =B17+1 -> 44191 | C18: =TEXT(A18,"ddd") -> qua | L18: =IFERROR((F18-E18)+(H18-G18)+(J18-I18)-K18,0) -> 0 | M18: =IFERROR(J18-E18,0) -> 0 | O18: =U18 -> 0 | U18: =V18+X18 -> 0 | V18: =IFERROR(W18-Z18,0) -> 0 | W18: =IF(AND(E18>=$AB$19,E18<=$AB$20),$AB$20,IF(AND(E18>=$AB$17,E18<=$AB$18),$AB$17,0)) -> 0 | X18: =IFERROR(AA18-Y18,0) -> 0 | Y18: =IF(AND(J18>=$AB$19,J18<=$AB$20),$AB$20,IF(AND(J18>=$AB$17,J18<=$AB$18),$AB$17,0)) -> 0 | Z18: =IF(AND($E18>=$AB$17,$E18<=$AB$18),$E18,IF(AND($E18>=$AB$19,$E18<=$AB$20),$E18,0)) -> 0 | AA18: =IF(AND($J18>=$AB$17,$J18<=$AB$18),$J18,IF(AND($J18>=$AB$19,$J18<=$AB$20),$J18,0)) -> 0 | AB18: 0.99930556
A19: =A18+1 -> 44652 | B19: =B18+1 -> 44192 | C19: =TEXT(A19,"ddd") -> qui | L19: =IFERROR((F19-E19)+(H19-G19)+(J19-I19)-K19,0) -> 0 | M19: =IFERROR(J19-E19,0) -> 0 | O19: =U19 -> 0 | U19: =V19+X19 -> 0 | V19: =IFERROR(W19-Z19,0) -> 0 | W19: =IF(AND(E19>=$AB$19,E19<=$AB$20),$AB$20,IF(AND(E19>=$AB$17,E19<=$AB$18),$AB$17,0)) -> 0 | X19: =IFERROR(AA19-Y19,0) -> 0 | Y19: =IF(AND(J19>=$AB$19,J19<=$AB$20),$AB$20,IF(AND(J19>=$AB$17,J19<=$AB$18),$AB$17,0)) -> 0 | Z19: =IF(AND($E19>=$AB$17,$E19<=$AB$18),$E19,IF(AND($E19>=$AB$19,$E19<=$AB$20),$E19,0)) -> 0 | AA19: =IF(AND($J19>=$AB$17,$J19<=$AB$18),$J19,IF(AND($J19>=$AB$19,$J19<=$AB$20),$J19,0)) -> 0 | AB19: 0.00069444444
A20: =A19+1 -> 44653 | B20: =B19+1 -> 44193 | C20: =TEXT(A20,"ddd") -> sex | L20: =IFERROR((F20-E20)+(H20-G20)+(J20-I20)-K20,0) -> 0 | M20: =IFERROR(J20-E20,0) -> 0 | O20: =U20 -> 0 | U20: =V20+X20 -> 0 | V20: =IFERROR(W20-Z20,0) -> 0 | W20: =IF(AND(E20>=$AB$19,E20<=$AB$20),$AB$20,IF(AND(E20>=$AB$17,E20<=$AB$18),$AB$17,0)) -> 0 | X20: =IFERROR(AA20-Y20,0) -> 0 | Y20: =IF(AND(J20>=$AB$19,J20<=$AB$20),$AB$20,IF(AND(J20>=$AB$17,J20<=$AB$18),$AB$17,0)) -> 0 | Z20: =IF(AND($E20>=$AB$17,$E20<=$AB$18),$E20,IF(AND($E20>=$AB$19,$E20<=$AB$20),$E20,0)) -> 0 | AA20: =IF(AND($J20>=$AB$17,$J20<=$AB$18),$J20,IF(AND($J20>=$AB$19,$J20<=$AB$20),$J20,0)) -> 0 | AB20: 0.20833333
A21: =A20+1 -> 44654 | B21: =B20+1 -> 44194 | C21: =TEXT(A21,"ddd") -> sáb | L21: =IFERROR((F21-E21)+(H21-G21)+(J21-I21)-K21,0) -> 0 | M21: =IFERROR(J21-E21,0) -> 0 | O21: =U21 -> 0 | U21: =V21+X21 -> 0 | V21: =IFERROR(W21-Z21,0) -> 0 | W21: =IF(AND(E21>=$AB$19,E21<=$AB$20),$AB$20,IF(AND(E21>=$AB$17,E21<=$AB$18),$AB$17,0)) -> 0 | X21: =IFERROR(AA21-Y21,0) -> 0 | Y21: =IF(AND(J21>=$AB$19,J21<=$AB$20),$AB$20,IF(AND(J21>=$AB$17,J21<=$AB$18),$AB$17,0)) -> 0 | Z21: =IF(AND($E21>=$AB$17,$E21<=$AB$18),$E21,IF(AND($E21>=$AB$19,$E21<=$AB$20),$E21,0)) -> 0 | AA21: =IF(AND($J21>=$AB$17,$J21<=$AB$18),$J21,IF(AND($J21>=$AB$19,$J21<=$AB$20),$J21,0)) -> 0
A22: =A21+1 -> 44655 | B22: =B21+1 -> 44195 | C22: =TEXT(A22,"ddd") -> dom | L22: =IFERROR((F22-E22)+(H22-G22)+(J22-I22)-K22,0) -> 0 | M22: =IFERROR(J22-E22,0) -> 0 | O22: =U22 -> 0 | U22: =V22+X22 -> 0 | V22: =IFERROR(W22-Z22,0) -> 0 | W22: =IF(AND(E22>=$AB$19,E22<=$AB$20),$AB$20,IF(AND(E22>=$AB$17,E22<=$AB$18),$AB$17,0)) -> 0 | X22: =IFERROR(AA22-Y22,0) -> 0 | Y22: =IF(AND(J22>=$AB$19,J22<=$AB$20),$AB$20,IF(AND(J22>=$AB$17,J22<=$AB$18),$AB$17,0)) -> 0 | Z22: =IF(AND($E22>=$AB$17,$E22<=$AB$18),$E22,IF(AND($E22>=$AB$19,$E22<=$AB$20),$E22,0)) -> 0 | AA22: =IF(AND($J22>=$AB$17,$J22<=$AB$18),$J22,IF(AND($J22>=$AB$19,$J22<=$AB$20),$J22,0)) -> 0
A23: =A22+1 -> 44656 | B23: =B22+1 -> 44196 | C23: =TEXT(A23,"ddd") -> seg | L23: =IFERROR((F23-E23)+(H23-G23)+(J23-I23)-K23,0) -> 0 | M23: =IFERROR(J23-E23,0) -> 0 | O23: =U23 -> 0 | U23: =V23+X23 -> 0 | V23: =IFERROR(W23-Z23,0) -> 0 | W23: =IF(AND(E23>=$AB$19,E23<=$AB$20),$AB$20,IF(AND(E23>=$AB$17,E23<=$AB$18),$AB$17,0)) -> 0 | X23: =IFERROR(AA23-Y23,0) -> 0 | Y23: =IF(AND(J23>=$AB$19,J23<=$AB$20),$AB$20,IF(AND(J23>=$AB$17,J23<=$AB$18),$AB$17,0)) -> 0 | Z23: =IF(AND($E23>=$AB$17,$E23<=$AB$18),$E23,IF(AND($E23>=$AB$19,$E23<=$AB$20),$E23,0)) -> 0 | AA23: =IF(AND($J23>=$AB$17,$J23<=$AB$18),$J23,IF(AND($J23>=$AB$19,$J23<=$AB$20),$J23,0)) -> 0
A24: =A23+1 -> 44657 | B24: =B23+1 -> 44197 | C24: =TEXT(A24,"ddd") -> ter | L24: =IFERROR((F24-E24)+(H24-G24)+(J24-I24)-K24,0) -> 0 | M24: =IFERROR(J24-E24,0) -> 0 | O24: =U24 -> 0 | U24: =V24+X24 -> 0 | V24: =IFERROR(W24-Z24,0) -> 0 | W24: =IF(AND(E24>=$AB$19,E24<=$AB$20),$AB$20,IF(AND(E24>=$AB$17,E24<=$AB$18),$AB$17,0)) -> 0 | X24: =IFERROR(AA24-Y24,0) -> 0 | Y24: =IF(AND(J24>=$AB$19,J24<=$AB$20),$AB$20,IF(AND(J24>=$AB$17,J24<=$AB$18),$AB$17,0)) -> 0 | Z24: =IF(AND($E24>=$AB$17,$E24<=$AB$18),$E24,IF(AND($E24>=$AB$19,$E24<=$AB$20),$E24,0)) -> 0 | AA24: =IF(AND($J24>=$AB$17,$J24<=$AB$18),$J24,IF(AND($J24>=$AB$19,$J24<=$AB$20),$J24,0)) -> 0
A25: =A24+1 -> 44658 | B25: =B24+1 -> 44198 | C25: =TEXT(A25,"ddd") -> qua | L25: =IFERROR((F25-E25)+(H25-G25)+(J25-I25)-K25,0) -> 0 | M25: =IFERROR(J25-E25,0) -> 0 | O25: =U25 -> 0 | U25: =V25+X25 -> 0 | V25: =IFERROR(W25-Z25,0) -> 0 | W25: =IF(AND(E25>=$AB$19,E25<=$AB$20),$AB$20,IF(AND(E25>=$AB$17,E25<=$AB$18),$AB$17,0)) -> 0 | X25: =IFERROR(AA25-Y25,0) -> 0 | Y25: =IF(AND(J25>=$AB$19,J25<=$AB$20),$AB$20,IF(AND(J25>=$AB$17,J25<=$AB$18),$AB$17,0)) -> 0 | Z25: =IF(AND($E25>=$AB$17,$E25<=$AB$18),$E25,IF(AND($E25>=$AB$19,$E25<=$AB$20),$E25,0)) -> 0 | AA25: =IF(AND($J25>=$AB$17,$J25<=$AB$18),$J25,IF(AND($J25>=$AB$19,$J25<=$AB$20),$J25,0)) -> 0
A26: =A25+1 -> 44659 | B26: =B25+1 -> 44199 | C26: =TEXT(A26,"ddd") -> qui | L26: =IFERROR((F26-E26)+(H26-G26)+(J26-I26)-K26,0) -> 0 | M26: =IFERROR(J26-E26,0) -> 0 | O26: =U26 -> 0 | U26: =V26+X26 -> 0 | V26: =IFERROR(W26-Z26,0) -> 0 | W26: =IF(AND(E26>=$AB$19,E26<=$AB$20),$AB$20,IF(AND(E26>=$AB$17,E26<=$AB$18),$AB$17,0)) -> 0 | X26: =IFERROR(AA26-Y26,0) -> 0 | Y26: =IF(AND(J26>=$AB$19,J26<=$AB$20),$AB$20,IF(AND(J26>=$AB$17,J26<=$AB$18),$AB$17,0)) -> 0 | Z26: =IF(AND($E26>=$AB$17,$E26<=$AB$18),$E26,IF(AND($E26>=$AB$19,$E26<=$AB$20),$E26,0)) -> 0 | AA26: =IF(AND($J26>=$AB$17,$J26<=$AB$18),$J26,IF(AND($J26>=$AB$19,$J26<=$AB$20),$J26,0)) -> 0
A27: =A26+1 -> 44660 | B27: =B26+1 -> 44200 | C27: =TEXT(A27,"ddd") -> sex | L27: =IFERROR((F27-E27)+(H27-G27)+(J27-I27)-K27,0) -> 0 | M27: =IFERROR(J27-E27,0) -> 0 | O27: =U27 -> 0 | U27: =V27+X27 -> 0 | V27: =IFERROR(W27-Z27,0) -> 0 | W27: =IF(AND(E27>=$AB$19,E27<=$AB$20),$AB$20,IF(AND(E27>=$AB$17,E27<=$AB$18),$AB$17,0)) -> 0 | X27: =IFERROR(AA27-Y27,0) -> 0 | Y27: =IF(AND(J27>=$AB$19,J27<=$AB$20),$AB$20,IF(AND(J27>=$AB$17,J27<=$AB$18),$AB$17,0)) -> 0 | Z27: =IF(AND($E27>=$AB$17,$E27<=$AB$18),$E27,IF(AND($E27>=$AB$19,$E27<=$AB$20),$E27,0)) -> 0 | AA27: =IF(AND($J27>=$AB$17,$J27<=$AB$18),$J27,IF(AND($J27>=$AB$19,$J27<=$AB$20),$J27,0)) -> 0
A28: =A27+1 -> 44661 | B28: =B27+1 -> 44201 | C28: =TEXT(A28,"ddd") -> sáb | L28: =IFERROR((F28-E28)+(H28-G28)+(J28-I28)-K28,0) -> 0 | M28: =IFERROR(J28-E28,0) -> 0 | O28: =U28 -> 0 | U28: =V28+X28 -> 0 | V28: =IFERROR(W28-Z28,0) -> 0 | W28: =IF(AND(E28>=$AB$19,E28<=$AB$20),$AB$20,IF(AND(E28>=$AB$17,E28<=$AB$18),$AB$17,0)) -> 0 | X28: =IFERROR(AA28-Y28,0) -> 0 | Y28: =IF(AND(J28>=$AB$19,J28<=$AB$20),$AB$20,IF(AND(J28>=$AB$17,J28<=$AB$18),$AB$17,0)) -> 0 | Z28: =IF(AND($E28>=$AB$17,$E28<=$AB$18),$E28,IF(AND($E28>=$AB$19,$E28<=$AB$20),$E28,0)) -> 0 | AA28: =IF(AND($J28>=$AB$17,$J28<=$AB$18),$J28,IF(AND($J28>=$AB$19,$J28<=$AB$20),$J28,0)) -> 0
A29: =A28+1 -> 44662 | B29: =B28+1 -> 44202 | C29: =TEXT(A29,"ddd") -> dom | L29: =IFERROR((F29-E29)+(H29-G29)+(J29-I29)-K29,0) -> 0 | M29: =IFERROR(J29-E29,0) -> 0 | O29: =U29 -> 0 | U29: =V29+X29 -> 0 | V29: =IFERROR(W29-Z29,0) -> 0 | W29: =IF(AND(E29>=$AB$19,E29<=$AB$20),$AB$20,IF(AND(E29>=$AB$17,E29<=$AB$18),$AB$17,0)) -> 0 | X29: =IFERROR(AA29-Y29,0) -> 0 | Y29: =IF(AND(J29>=$AB$19,J29<=$AB$20),$AB$20,IF(AND(J29>=$AB$17,J29<=$AB$18),$AB$17,0)) -> 0 | Z29: =IF(AND($E29>=$AB$17,$E29<=$AB$18),$E29,IF(AND($E29>=$AB$19,$E29<=$AB$20),$E29,0)) -> 0 | AA29: =IF(AND($J29>=$AB$17,$J29<=$AB$18),$J29,IF(AND($J29>=$AB$19,$J29<=$AB$20),$J29,0)) -> 0
A30: =A29+1 -> 44663 | B30: =B29+1 -> 44203 | C30: =TEXT(A30,"ddd") -> seg | L30: =IFERROR((F30-E30)+(H30-G30)+(J30-I30)-K30,0) -> 0 | M30: =IFERROR(J30-E30,0) -> 0 | O30: =U30 -> 0 | U30: =V30+X30 -> 0 | V30: =IFERROR(W30-Z30,0) -> 0 | W30: =IF(AND(E30>=$AB$19,E30<=$AB$20),$AB$20,IF(AND(E30>=$AB$17,E30<=$AB$18),$AB$17,0)) -> 0 | X30: =IFERROR(AA30-Y30,0) -> 0 | Y30: =IF(AND(J30>=$AB$19,J30<=$AB$20),$AB$20,IF(AND(J30>=$AB$17,J30<=$AB$18),$AB$17,0)) -> 0 | Z30: =IF(AND($E30>=$AB$17,$E30<=$AB$18),$E30,IF(AND($E30>=$AB$19,$E30<=$AB$20),$E30,0)) -> 0 | AA30: =IF(AND($J30>=$AB$17,$J30<=$AB$18),$J30,IF(AND($J30>=$AB$19,$J30<=$AB$20),$J30,0)) -> 0
A31: =A30+1 -> 44664 | B31: =B30+1 -> 44204 | C31: =TEXT(A31,"ddd") -> ter | L31: =IFERROR((F31-E31)+(H31-G31)+(J31-I31)-K31,0) -> 0 | M31: =IFERROR(J31-E31,0) -> 0 | O31: =U31 -> 0 | U31: =V31+X31 -> 0 | V31: =IFERROR(W31-Z31,0) -> 0 | W31: =IF(AND(E31>=$AB$19,E31<=$AB$20),$AB$20,IF(AND(E31>=$AB$17,E31<=$AB$18),$AB$17,0)) -> 0 | X31: =IFERROR(AA31-Y31,0) -> 0 | Y31: =IF(AND(J31>=$AB$19,J31<=$AB$20),$AB$20,IF(AND(J31>=$AB$17,J31<=$AB$18),$AB$17,0)) -> 0 | Z31: =IF(AND($E31>=$AB$17,$E31<=$AB$18),$E31,IF(AND($E31>=$AB$19,$E31<=$AB$20),$E31,0)) -> 0 | AA31: =IF(AND($J31>=$AB$17,$J31<=$AB$18),$J31,IF(AND($J31>=$AB$19,$J31<=$AB$20),$J31,0)) -> 0
A32: =A31+1 -> 44665 | B32: =B31+1 -> 44205 | C32: =TEXT(A32,"ddd") -> qua | L32: =IFERROR((F32-E32)+(H32-G32)+(J32-I32)-K32,0) -> 0 | M32: =IFERROR(J32-E32,0) -> 0 | O32: =U32 -> 0 | U32: =V32+X32 -> 0 | V32: =IFERROR(W32-Z32,0) -> 0 | W32: =IF(AND(E32>=$AB$19,E32<=$AB$20),$AB$20,IF(AND(E32>=$AB$17,E32<=$AB$18),$AB$17,0)) -> 0 | X32: =IFERROR(AA32-Y32,0) -> 0 | Y32: =IF(AND(J32>=$AB$19,J32<=$AB$20),$AB$20,IF(AND(J32>=$AB$17,J32<=$AB$18),$AB$17,0)) -> 0 | Z32: =IF(AND($E32>=$AB$17,$E32<=$AB$18),$E32,IF(AND($E32>=$AB$19,$E32<=$AB$20),$E32,0)) -> 0 | AA32: =IF(AND($J32>=$AB$17,$J32<=$AB$18),$J32,IF(AND($J32>=$AB$19,$J32<=$AB$20),$J32,0)) -> 0
... A42: =A41+1 -> 44675 | B42: =B41+1 -> 44215 | C42: =TEXT(A42,"ddd") -> sáb | L42: =IFERROR((F42-E42)+(H42-G42)+(J42-I42)-K42,0) -> 0 | M42: =IFERROR(J42-E42,0) -> 0 | O42: =U42 -> 0 | U42: =V42+X42 -> 0 | V42: =IFERROR(W42-Z42,0) -> 0 | W42: =IF(AND(E42>=$AB$19,E42<=$AB$20),$AB$20,IF(AND(E42>=$AB$17,E42<=$AB$18),$AB$17,0)) -> 0 | X42: =IFERROR(AA42-Y42,0) -> 0 | Y42: =IF(AND(J42>=$AB$19,J42<=$AB$20),$AB$20,IF(AND(J42>=$AB$17,J42<=$AB$18),$AB$17,0)) -> 0 | Z42: =IF(AND($E42>=$AB$17,$E42<=$AB$18),$E42,IF(AND($E42>=$AB$19,$E42<=$AB$20),$E42,0)) -> 0 | AA42: =IF(AND($J42>=$AB$17,$J42<=$AB$18),$J42,IF(AND($J42>=$AB$19,$J42<=$AB$20),$J42,0)) -> 0
A43: TOTAL | L43: =SUM(L12:L42) -> 0 | N43: =SUM(N12:N42) -> 0 | O43: =SUM(O12:O42) -> 0 | P43: =SUM(P12:P42) -> 0
L44: 9.1666667
A45: FALTAS | D45: =COUNTIF($E$12:$E$42,"FALTA") -> 0 | F45: JUSTIFICADAS: ___________________ NÃO JUSTIFICADAS: ___________________ | P45: ASSINATURA COLABORADOR
A48: FOLGAS | D48: =COUNTIF($E$12:$E$42,"FOLGA") -> 0 | F48: SUSPENÇÃO | I48: =COUNTIF($E$12:$E$42,"SUSPENSÃO") -> 0 | K48: ADVERTÊNCIA | O48: =COUNTIF($E$12:$E$42,"ADVERTENCIA") -> 0
P49: VISTO SUPERVISOR OPERACIONAL
J50: 1ºQ | L50: 2ºQ
A51: Hora Extra 60% | I51: =(L43-L44)*40% -> -3.6666667 | K51: =I51*24 -> -88 | N51: 21.79 | O51: =K51*N51 -> -1917.52
A52: Diárias | I52: =IFERROR(COUNTIFS($B$17:$B$42,$J$50,$N$12:$N$42,"38,00"),"") | K52: =IFERROR(COUNTIFS($B$17:$B$42,$L$50,$N$12:$N$42,"38,00"),"") | O52: =SUM(N12:N42) -> 0
...

Sheet GRAFICO
B2: NOME DE GUERRA | C2: HR ATUAL | D2: HORA META | E2: EXTRAS | F2: STATUS | N2: FOLGAS- FALTAS - ATESTADOS
C3: 8.1854167 | D3: 9.1666667 | E3: =C3-D3 -> -0.98125 | F3: =IF(C3<D3,"NEGATIVO","EXTRAS") -> NEGATIVO
C4: 8.08125 | D4: 9.1666667 | E4: =C4-D4 -> -1.0854167 | F4: =IF(C4<D4,"NEGATIVO","EXTRAS") -> NEGATIVO
C5: 5.3090278 | D5: 9.1666667 | E5: =C5-D5 -> -3.8576389 | F5: =IF(C5<D5,"NEGATIVO","EXTRAS") -> NEGATIVO
C6: 6.3972222 | D6: 9.1666667 | E6: =C6-D6 -> -2.7694444 | F6: =IF(C6<D6,"NEGATIVO","EXTRAS") -> NEGATIVO
C7: 4.9430556 | D7: 9.1666667 | E7: =C7-D7 -> -4.2236111 | F7: =IF(C7<D7,"NEGATIVO","EXTRAS") -> NEGATIVO | N7: FÉRIAS
C8: 9.4868056 | D8: 9.1666667 | E8: =C8-D8 -> 0.32013889 | F8: =IF(C8<D8,"NEGATIVO","EXTRAS") -> EXTRAS
C9: 9.8270833 | D9: 9.1666667 | E9: =C9-D9 -> 0.66041667 | F9: =IF(C9<D9,"NEGATIVO","EXTRAS") -> EXTRAS | N9: OUTROS
C10: 7.1736111 | D10: 9.1666667 | E10: =C10-D10 -> -1.9930556 | F10: =IF(C10<D10,"NEGATIVO","EXTRAS") -> NEGATIVO

Sheet 26 a 10
A1: RESUMO QUINZENAL DE DIÁRIAS - ABRIL X MAIO - REFERENTE 26/04 A 10/05
A3: NOME DO AGENTE | B3: NOME GUERRA | C3: QTDE. | D3: PAGAR | E3: DIÁRIA | F3: À PAGAR | G3: OBSERVAÇÃO
A4: ADILSON PEREIRA DA SILVA | B4: ADILSON | C4: 0 | D4: 0 | E4: 40 | F4: =Table_13[[#This Row],[PAGAR ]]*Table_13[[#This Row],[DIÁRIA]] -> 0
A5: MARCO APARECIDO DA SILVA | B5: APARECIDO | C5: 0 | D5: 0 | E5: 40 | F5: =Table_13[[#This Row],[PAGAR ]]*Table_13[[#This Row],[DIÁRIA]] -> 0
A6: GABRIEL DAMIAO RAMIRES DOS SANTOS | B6: DAMIÃO | C6: 0 | D6: 0 | E6: 40 | F6: =Table_13[[#This Row],[PAGAR ]]*Table_13[[#This Row],[DIÁRIA]] -> 0
A7: EMERSON JOSE DA SILVA | B7: EMERSON | C7: 0 | D7: 0 | E7: 40 | F7: =Table_13[[#This Row],[PAGAR ]]*Table_13[[#This Row],[DIÁRIA]] -> 0
A8: EVERSON JOSE DA SILVA | B8: EVERSON | C8: 0 | D8: 0 | E8: 40 | F8: =Table_13[[#This Row],[PAGAR ]]*Table_13[[#This Row],[DIÁRIA]] -> 0
A9: LUIS FAUSTINO | B9: FAUSTINO | C9: 0 | D9: 0 | E9: 40 | F9: =Table_13[[#This Row],[PAGAR ]]*Table_13[[#This Row],[DIÁRIA]] -> 0
A10: IOLANDO CARMARGO DE CARVALHO | B10: IOLANDO | C10: 0 | D10: 0 | E10: 40 | F10: =Table_13[[#This Row],[PAGAR ]]*Table_13[[#This Row],[DIÁRIA]] -> 0
A11: JAIRO JOAQUIM DE SANTANA | B11: JAIRO | C11: 0 | D11: 0 | E11: 40 | F11: =Table_13[[#This Row],[PAGAR ]]*Table_13[[#This Row],[DIÁRIA]] -> 0
A12: JEFERSON YUKIO YAMADA | B12: JEFERSON | C12: 0 | D12: 0 | E12: 40 | F12: =Table_13[[#This Row],[PAGAR ]]*Table_13[[#This Row],[DIÁRIA]] -> 0
A13: ISRAEL DA SILVA JOSINO | B13: JOSINO | C13: 0 | D13: 0 | E13: 40 | F13: =Table_13[[#This Row],[PAGAR ]]*Table_13[[#This Row],[DIÁRIA]] -> 0
A14: LOURENÇO VITOR DA SILVA | B14: LOURENÇO | C14: 0 | D14: 0 | E14: 40 | F14: =Table_13[[#This Row],[PAGAR ]]*Table_13[[#This Row],[DIÁRIA]] -> 0
A15: ANTONIO ROBERTO SABINO | B15: SABINO | C15: 0 | D15: 0 | E15: 40 | F15: =Table_13[[#This Row],[PAGAR ]]*Table_13[[#This Row],[DIÁRIA]] -> 0
... A18: VANDERLEI ALVES MARCELINO | B18: VANDERLEI | C18: 0 | D18: 0 | E18: 40 | F18: =Table_13[[#This Row],[PAGAR ]]*Table_13[[#This Row],[DIÁRIA]] -> 0
E19: 40 | F19: =Table_13[[#This Row],[PAGAR ]]*Table_13[[#This Row],[DIÁRIA]] -> 0
E20: 40 | F20: =Table_13[[#This Row],[PAGAR ]]*Table_13[[#This Row],[DIÁRIA]] -> 0
E21: 40 | F21: =Table_13[[#This Row],[PAGAR ]]*Table_13[[#This Row],[DIÁRIA]] -> 0
E22: 40 | F22: =Table_13[[#This Row],[PAGAR ]]*Table_13[[#This Row],[DIÁRIA]] -> 0
E23: 40 | F23: =Table_13[[#This Row],[PAGAR ]]*Table_13[[#This Row],[DIÁRIA]] -> 0
E24: 40 | F24: =Table_13[[#This Row],[PAGAR ]]*Table_13[[#This Row],[DIÁRIA]] -> 0
B25: TOTAL | F25: =SUM(Table_13[À PAGAR]) -> 0

Sheet 11 a 25
A1: RESUMO QUINZENAL DE DIÁRIAS - ABRIL X MAIO - REFERENTE 10/05 a 25/05
A3: NOME DO AGENTE | B3: NOME GUERRA | C3: QTDE. | D3: PAGAR | E3: DIÁRIA | F3: À PAGAR | G3: OBSERVAÇÃO
C4: 0 | D4: 0 | E4: 40 | F4: =Table_132[[#This Row],[PAGAR ]]*Table_132[[#This Row],[DIÁRIA]] -> 0
C5: 0 | D5: 0 | E5: 40 | F5: =Table_132[[#This Row],[PAGAR ]]*Table_132[[#This Row],[DIÁRIA]] -> 0
C6: 0 | D6: 0 | E6: 40 | F6: =Table_132[[#This Row],[PAGAR ]]*Table_132[[#This Row],[DIÁRIA]] -> 0
C7: 0 | D7: 0 | E7: 40 | F7: =Table_132[[#This Row],[PAGAR ]]*Table_132[[#This Row],[DIÁRIA]] -> 0
C8: 0 | D8: 0 | E8: 40 | F8: =Table_132[[#This Row],[PAGAR ]]*Table_132[[#This Row],[DIÁRIA]] -> 0
C9: 0 | D9: 0 | E9: 40 | F9: =Table_132[[#This Row],[PAGAR ]]*Table_132[[#This Row],[DIÁRIA]] -> 0
C10: 0 | D10: 0 | E10: 40 | F10: =Table_132[[#This Row],[PAGAR ]]*Table_132[[#This Row],[DIÁRIA]] -> 0
C11: 0 | D11: 0 | E11: 40 | F11: =Table_132[[#This Row],[PAGAR ]]*Table_132[[#This Row],[DIÁRIA]] -> 0
C12: 0 | D12: 0 | E12: 40 | F12: =Table_132[[#This Row],[PAGAR ]]*Table_132[[#This Row],[DIÁRIA]] -> 0
C13: 0 | D13: 0 | E13: 40 | F13: =Table_132[[#This Row],[PAGAR ]]*Table_132[[#This Row],[DIÁRIA]] -> 0
C14: 0 | D14: 0 | E14: 40 | F14: =Table_132[[#This Row],[PAGAR ]]*Table_132[[#This Row],[DIÁRIA]] -> 0
C15: 0 | D15: 0 | E15: 40 | F15: =Table_132[[#This Row],[PAGAR ]]*Table_132[[#This Row],[DIÁRIA]] -> 0
... C19: 0 | D19: 0 | E19: 40 | F19: =Table_132[[#This Row],[PAGAR ]]*Table_132[[#This Row],[DIÁRIA]] -> 0
B20: TOTAL | F20: =SUM(Table_132[À PAGAR]) -> 0

Sheet FOLHA OP 1
D1: EMPRESA: | Z1: Horário de Trabalho Interno | AA1: 0.75 | AB1: 0.00069444444 | AC1: Urbana 2 | AD1: 0.75
AA2: 38 | AC2: Urbana | AD2: 0.74930556
D3: ENDEREÇO: | L3: 02301-110 | Z3: Ficha Individual - Art 74/3 CLT | AA3: 0 | AC3: Folga | AD3: 0
D4: BAIRRO: | L4: SÃO PAULO | M4: UF: | N4: SP | Z4: Portaria Nº 3082 de 11/04/98
D5: CODIGO: 0000 | F5: NOME
Z6: MÊS
D7: CARGO : VIGILANTE DE ESCOLTA ARMADA | R7: RODOVIÁRIO | S7: 38 | Z7: 44316
D8: DEPTO/ SETOR/ SEÇÃO: 0001/ 0002 / 0000 | R8: URBANO | S8: 38
A10: DATA | C10: DIA | D10: ENTRADA | E10: REFEIÇÃO (ALMOÇO) | G10: REFEIÇÃO (JANTAR) | I10: SAÍDA | J10: VR | K10: DIARIA | L10: CAFÉ | M10: TOTAL HORAS | N10: ASS. FUNCIONÁRIO | Z10: OBSERVAÇÕES
E11: SAÍDA | F11: ENTRADA | G11: SAÍDA | H11: ENTRADA | R11: SOMA AD. NOT | S11: RESULTADO ENTRADA | T11: REFERENCIA ENTRADA | U11: RESULTADO SAIDA | V11: REFERENCIA SAIDA | W11: CONDIÇÃO DE SOMA ENTRADA | X11: CONDIÇÃO DE SOMA SAIDA | Y11: REFERENCIA HORAS EM NUMEROS | AB11: Q1 | AC11: =COUNTIF(#REF!,$AA$2) -> #REF! | AD11: =SUM(#REF!) -> #REF!
A12: 44341 | B12: =VLOOKUP($A12,Datas!$B:$E,4,0) -> #N/A | C12: {=TEXT(INDEX($A$12:$A$41,MATCH(Datas!A2&Datas!C2&Datas!D2,Datas!$A$2:$A$336&Datas!$C$2:$C$336&Datas!$D$2:$D$336,0)),"DDD")} -> seg | R12: =S12+U12 -> 0 | S12: =IFERROR(T12-W12,0) -> 0 | T12: =IF(AND(D12>=$Y$14,D12<=$Y$15),$Y$15,IF(AND(D12>=$Y$12,D12<=$Y$13),$Y$12,0)) -> 0 | U12: =IFERROR(X12-V12,0) -> 0 | V12: =IF(AND(I12>=$Y$14,I12<=$Y$15),$Y$15,IF(AND(I12>=$Y$12,I12<=$Y$13),$Y$12,0)) -> 0 | W12: =IF(AND($D12>=$Y$12,$D12<=$Y$13),$D12,IF(AND($D12>=$Y$14,$D12<=$Y$15),$D12,0)) -> 0 | X12: =IF(AND($I12>=$Y$12,$I12<=$Y$13),$I12,IF(AND($I12>=$Y$14,$I12<=$Y$15),$I12,0)) -> 0 | Y12: 0.91666667 | AB12: Q2 | AC12: =COUNTIF(#REF!,$AA$2) -> #REF! | AD12: =SUM(#REF!) -> #REF!
A13: =A12+1 -> 44342 | B13: =VLOOKUP($A13,Datas!$B:$E,4,0) -> #N/A | C13: {=TEXT(INDEX($A$12:$A$41,MATCH(Datas!A3&Datas!C3&Datas!D3,Datas!$A$2:$A$336&Datas!$C$2:$C$336&Datas!$D$2:$D$336,0)),"DDD")} -> ter | R13: =S13+U13 -> 0 | S13: =IFERROR(T13-W13,0) -> 0 | T13: =IF(AND(D13>=$Y$14,D13<=$Y$15),$Y$15,IF(AND(D13>=$Y$12,D13<=$Y$13),$Y$12,0)) -> 0 | U13: =IFERROR(X13-V13,0) -> 0 | V13: =IF(AND(I13>=$Y$14,I13<=$Y$15),$Y$15,IF(AND(I13>=$Y$12,I13<=$Y$13),$Y$12,0)) -> 0 | W13: =IF(AND($D13>=$Y$12,$D13<=$Y$13),$D13,IF(AND($D13>=$Y$14,$D13<=$Y$15),$D13,0)) -> 0 | X13: =IF(AND($I13>=$Y$12,$I13<=$Y$13),$I13,IF(AND($I13>=$Y$14,$I13<=$Y$15),$I13,0)) -> 0 | Y13: 0.99930556
A14: =A13+1 -> 44343 | B14: =VLOOKUP($A14,Datas!$B:$E,4,0) -> #N/A | C14: {=TEXT(INDEX($A$12:$A$41,MATCH(Datas!A4&Datas!C4&Datas!D4,Datas!$A$2:$A$336&Datas!$C$2:$C$336&Datas!$D$2:$D$336,0)),"DDD")} -> qua | R14: =S14+U14 -> 0 | S14: =IFERROR(T14-W14,0) -> 0 | T14: =IF(AND(D14>=$Y$14,D14<=$Y$15),$Y$15,IF(AND(D14>=$Y$12,D14<=$Y$13),$Y$12,0)) -> 0 | U14: =IFERROR(X14-V14,0) -> 0 | V14: =IF(AND(I14>=$Y$14,I14<=$Y$15),$Y$15,IF(AND(I14>=$Y$12,I14<=$Y$13),$Y$12,0)) -> 0 | W14: =IF(AND($D14>=$Y$12,$D14<=$Y$13),$D14,IF(AND($D14>=$Y$14,$D14<=$Y$15),$D14,0)) -> 0 | X14: =IF(AND($I14>=$Y$12,$I14<=$Y$13),$I14,IF(AND($I14>=$Y$14,$I14<=$Y$15),$I14,0)) -> 0 | Y14: 0.00069444444
A15: =A14+1 -> 44344 | B15: =VLOOKUP($A15,Datas!$B:$E,4,0) -> #N/A | C15: {=TEXT(INDEX($A$12:$A$41,MATCH(Datas!A5&Datas!C5&Datas!D5,Datas!$A$2:$A$336&Datas!$C$2:$C$336&Datas!$D$2:$D$336,0)),"DDD")} -> qui | R15: =S15+U15 -> 0 | S15: =IFERROR(T15-W15,0) -> 0 | T15: =IF(AND(D15>=$Y$14,D15<=$Y$15),$Y$15,IF(AND(D15>=$Y$12,D15<=$Y$13),$Y$12,0)) -> 0 | U15: =IFERROR(X15-V15,0) -> 0 | V15: =IF(AND(I15>=$Y$14,I15<=$Y$15),$Y$15,IF(AND(I15>=$Y$12,I15<=$Y$13),$Y$12,0)) -> 0 | W15: =IF(AND($D15>=$Y$12,$D15<=$Y$13),$D15,IF(AND($D15>=$Y$14,$D15<=$Y$15),$D15,0)) -> 0 | X15: =IF(AND($I15>=$Y$12,$I15<=$Y$13),$I15,IF(AND($I15>=$Y$14,$I15<=$Y$15),$I15,0)) -> 0 | Y15: 0.20833333
A16: =A15+1 -> 44345 | B16: =VLOOKUP($A16,Datas!$B:$E,4,0) -> #N/A | C16: {=TEXT(INDEX($A$12:$A$41,MATCH(Datas!A6&Datas!C6&Datas!D6,Datas!$A$2:$A$336&Datas!$C$2:$C$336&Datas!$D$2:$D$336,0)),"DDD")} -> sex | R16: =S16+U16 -> 0 | S16: =IFERROR(T16-W16,0) -> 0 | T16: =IF(AND(D16>=$Y$14,D16<=$Y$15),$Y$15,IF(AND(D16>=$Y$12,D16<=$Y$13),$Y$12,0)) -> 0 | U16: =IFERROR(X16-V16,0) -> 0 | V16: =IF(AND(I16>=$Y$14,I16<=$Y$15),$Y$15,IF(AND(I16>=$Y$12,I16<=$Y$13),$Y$12,0)) -> 0 | W16: =IF(AND($D16>=$Y$12,$D16<=$Y$13),$D16,IF(AND($D16>=$Y$14,$D16<=$Y$15),$D16,0)) -> 0 | X16: =IF(AND($I16>=$Y$12,$I16<=$Y$13),$I16,IF(AND($I16>=$Y$14,$I16<=$Y$15),$I16,0)) -> 0
A17: =A16+1 -> 44346 | B17: =VLOOKUP($A17,Datas!$B:$E,4,0) -> #N/A | C17: {=TEXT(INDEX($A$12:$A$41,MATCH(Datas!A7&Datas!C7&Datas!D7,Datas!$A$2:$A$336&Datas!$C$2:$C$336&Datas!$D$2:$D$336,0)),"DDD")} -> sáb | R17: =S17+U17 -> 0 | S17: =IFERROR(T17-W17,0) -> 0 | T17: =IF(AND(D17>=$Y$14,D17<=$Y$15),$Y$15,IF(AND(D17>=$Y$12,D17<=$Y$13),$Y$12,0)) -> 0 | U17: =IFERROR(X17-V17,0) -> 0 | V17: =IF(AND(I17>=$Y$14,I17<=$Y$15),$Y$15,IF(AND(I17>=$Y$12,I17<=$Y$13),$Y$12,0)) -> 0 | W17: =IF(AND($D17>=$Y$12,$D17<=$Y$13),$D17,IF(AND($D17>=$Y$14,$D17<=$Y$15),$D17,0)) -> 0 | X17: =IF(AND($I17>=$Y$12,$I17<=$Y$13),$I17,IF(AND($I17>=$Y$14,$I17<=$Y$15),$I17,0)) -> 0
A18: =A17+1 -> 44347 | B18: =VLOOKUP($A18,Datas!$B:$E,4,0) -> #N/A | C18: {=TEXT(INDEX($A$12:$A$41,MATCH(Datas!A8&Datas!C8&Datas!D8,Datas!$A$2:$A$336&Datas!$C$2:$C$336&Datas!$D$2:$D$336,0)),"DDD")} -> dom | R18: =S18+U18 -> 0 | S18: =IFERROR(T18-W18,0) -> 0 | T18: =IF(AND(D18>=$Y$14,D18<=$Y$15),$Y$15,IF(AND(D18>=$Y$12,D18<=$Y$13),$Y$12,0)) -> 0 | U18: =IFERROR(X18-V18,0) -> 0 | V18: =IF(AND(I18>=$Y$14,I18<=$Y$15),$Y$15,IF(AND(I18>=$Y$12,I18<=$Y$13),$Y$12,0)) -> 0 | W18: =IF(AND($D18>=$Y$12,$D18<=$Y$13),$D18,IF(AND($D18>=$Y$14,$D18<=$Y$15),$D18,0)) -> 0 | X18: =IF(AND($I18>=$Y$12,$I18<=$Y$13),$I18,IF(AND($I18>=$Y$14,$I18<=$Y$15),$I18,0)) -> 0
A19: =A18+1 -> 44348 | B19: =VLOOKUP($A19,Datas!$B:$E,4,0) -> #N/A | C19: {=TEXT(INDEX($A$12:$A$41,MATCH(Datas!A9&Datas!C9&Datas!D9,Datas!$A$2:$A$336&Datas!$C$2:$C$336&Datas!$D$2:$D$336,0)),"DDD")} -> seg | R19: =S19+U19 -> 0 | S19: =IFERROR(T19-W19,0) -> 0 | T19: =IF(AND(D19>=$Y$14,D19<=$Y$15),$Y$15,IF(AND(D19>=$Y$12,D19<=$Y$13),$Y$12,0)) -> 0 | U19: =IFERROR(X19-V19,0) -> 0 | V19: =IF(AND(I19>=$Y$14,I19<=$Y$15),$Y$15,IF(AND(I19>=$Y$12,I19<=$Y$13),$Y$12,0)) -> 0 | W19: =IF(AND($D19>=$Y$12,$D19<=$Y$13),$D19,IF(AND($D19>=$Y$14,$D19<=$Y$15),$D19,0)) -> 0 | X19: =IF(AND($I19>=$Y$12,$I19<=$Y$13),$I19,IF(AND($I19>=$Y$14,$I19<=$Y$15),$I19,0)) -> 0
A20: =A19+1 -> 44349 | B20: =VLOOKUP($A20,Datas!$B:$E,4,0) -> #N/A | C20: {=TEXT(INDEX($A$12:$A$41,MATCH(Datas!A10&Datas!C10&Datas!D10,Datas!$A$2:$A$336&Datas!$C$2:$C$336&Datas!$D$2:$D$336,0)),"DDD")} -> ter | R20: =S20+U20 -> 0 | S20: =IFERROR(T20-W20,0) -> 0 | T20: =IF(AND(D20>=$Y$14,D20<=$Y$15),$Y$15,IF(AND(D20>=$Y$12,D20<=$Y$13),$Y$12,0)) -> 0 | U20: =IFERROR(X20-V20,0) -> 0 | V20: =IF(AND(I20>=$Y$14,I20<=$Y$15),$Y$15,IF(AND(I20>=$Y$12,I20<=$Y$13),$Y$12,0)) -> 0 | W20: =IF(AND($D20>=$Y$12,$D20<=$Y$13),$D20,IF(AND($D20>=$Y$14,$D20<=$Y$15),$D20,0)) -> 0 | X20: =IF(AND($I20>=$Y$12,$I20<=$Y$13),$I20,IF(AND($I20>=$Y$14,$I20<=$Y$15),$I20,0)) -> 0
A21: =A20+1 -> 44350 | B21: =VLOOKUP($A21,Datas!$B:$E,4,0) -> #N/A | C21: {=TEXT(INDEX($A$12:$A$41,MATCH(Datas!A11&Datas!C11&Datas!D11,Datas!$A$2:$A$336&Datas!$C$2:$C$336&Datas!$D$2:$D$336,0)),"DDD")} -> qua | R21: =S21+U21 -> 0 | S21: =IFERROR(T21-W21,0) -> 0 | T21: =IF(AND(D21>=$Y$14,D21<=$Y$15),$Y$15,IF(AND(D21>=$Y$12,D21<=$Y$13),$Y$12,0)) -> 0 | U21: =IFERROR(X21-V21,0) -> 0 | V21: =IF(AND(I21>=$Y$14,I21<=$Y$15),$Y$15,IF(AND(I21>=$Y$12,I21<=$Y$13),$Y$12,0)) -> 0 | W21: =IF(AND($D21>=$Y$12,$D21<=$Y$13),$D21,IF(AND($D21>=$Y$14,$D21<=$Y$15),$D21,0)) -> 0 | X21: =IF(AND($I21>=$Y$12,$I21<=$Y$13),$I21,IF(AND($I21>=$Y$14,$I21<=$Y$15),$I21,0)) -> 0
A22: =A21+1 -> 44351 | B22: =VLOOKUP($A22,Datas!$B:$E,4,0) -> #N/A | C22: {=TEXT(INDEX($A$12:$A$41,MATCH(Datas!A12&Datas!C12&Datas!D12,Datas!$A$2:$A$336&Datas!$C$2:$C$336&Datas!$D$2:$D$336,0)),"DDD")} -> qui | R22: =S22+U22 -> 0 | S22: =IFERROR(T22-W22,0) -> 0 | T22: =IF(AND(D24>=$Y$14,D24<=$Y$15),$Y$15,IF(AND(D24>=$Y$12,D24<=$Y$13),$Y$12,0)) -> 0 | U22: =IFERROR(X22-V22,0) -> 0 | V22: =IF(AND(I22>=$Y$14,I22<=$Y$15),$Y$15,IF(AND(I22>=$Y$12,I22<=$Y$13),$Y$12,0)) -> 0 | W22: =IF(AND($D24>=$Y$12,$D24<=$Y$13),$D24,IF(AND($D24>=$Y$14,$D24<=$Y$15),$D24,0)) -> 0 | X22: =IF(AND($I22>=$Y$12,$I22<=$Y$13),$I22,IF(AND($I22>=$Y$14,$I22<=$Y$15),$I22,0)) -> 0
A23: =A22+1 -> 44352 | B23: =VLOOKUP($A23,Datas!$B:$E,4,0) -> #N/A | C23: {=TEXT(INDEX($A$12:$A$41,MATCH(Datas!A13&Datas!C13&Datas!D13,Datas!$A$2:$A$336&Datas!$C$2:$C$336&Datas!$D$2:$D$336,0)),"DDD")} -> sex | R23: =S23+U23 -> 0 | S23: =IFERROR(T23-W23,0) -> 0 | T23: =IF(AND(D23>=$Y$14,D23<=$Y$15),$Y$15,IF(AND(D23>=$Y$12,D23<=$Y$13),$Y$12,0)) -> 0 | U23: =IFERROR(X23-V23,0) -> 0 | V23: =IF(AND(I23>=$Y$14,I23<=$Y$15),$Y$15,IF(AND(I23>=$Y$12,I23<=$Y$13),$Y$12,0)) -> 0 | W23: =IF(AND($D23>=$Y$12,$D23<=$Y$13),$D23,IF(AND($D23>=$Y$14,$D23<=$Y$15),$D23,0)) -> 0 | X23: =IF(AND($I23>=$Y$12,$I23<=$Y$13),$I23,IF(AND($I23>=$Y$14,$I23<=$Y$15),$I23,0)) -> 0
A24: =A23+1 -> 44353 | B24: =VLOOKUP($A24,Datas!$B:$E,4,0) -> #N/A | C24: {=TEXT(INDEX($A$12:$A$41,MATCH(Datas!A14&Datas!C14&Datas!D14,Datas!$A$2:$A$336&Datas!$C$2:$C$336&Datas!$D$2:$D$336,0)),"DDD")} -> sáb | R24: =S24+U24 -> 0 | S24: =IFERROR(T24-W24,0) -> 0 | T24: =IF(AND(#REF!>=$Y$14,#REF!<=$Y$15),$Y$15,IF(AND(#REF!>=$Y$12,#REF!<=$Y$13),$Y$12,0)) -> #REF! | U24: =IFERROR(X24-V24,0) -> 0 | V24: =IF(AND(I24>=$Y$14,I24<=$Y$15),$Y$15,IF(AND(I24>=$Y$12,I24<=$Y$13),$Y$12,0)) -> 0 | W24: =IF(AND(#REF!>=$Y$12,#REF!<=$Y$13),#REF!,IF(AND(#REF!>=$Y$14,#REF!<=$Y$15),#REF!,0)) -> #REF! | X24: =IF(AND($I24>=$Y$12,$I24<=$Y$13),$I24,IF(AND($I24>=$Y$14,$I24<=$Y$15),$I24,0)) -> 0
A25: =A24+1 -> 44354 | B25: =VLOOKUP($A25,Datas!$B:$E,4,0) -> #N/A | C25: {=TEXT(INDEX($A$12:$A$41,MATCH(Datas!A15&Datas!C15&Datas!D15,Datas!$A$2:$A$336&Datas!$C$2:$C$336&Datas!$D$2:$D$336,0)),"DDD")} -> dom | R25: =S25+U25 -> 0 | S25: =IFERROR(T25-W25,0) -> 0 | T25: =IF(AND(D25>=$Y$14,D25<=$Y$15),$Y$15,IF(AND(D25>=$Y$12,D25<=$Y$13),$Y$12,0)) -> 0 | U25: =IFERROR(X25-V25,0) -> 0 | V25: =IF(AND(I25>=$Y$14,I25<=$Y$15),$Y$15,IF(AND(I25>=$Y$12,I25<=$Y$13),$Y$12,0)) -> 0 | W25: =IF(AND($D25>=$Y$12,$D25<=$Y$13),$D25,IF(AND($D25>=$Y$14,$D25<=$Y$15),$D25,0)) -> 0 | X25: =IF(AND($I25>=$Y$12,$I25<=$Y$13),$I25,IF(AND($I25>=$Y$14,$I25<=$Y$15),$I25,0)) -> 0
A26: =A25+1 -> 44355 | B26: =VLOOKUP($A26,Datas!$B:$E,4,0) -> #N/A | C26: {=TEXT(INDEX($A$12:$A$41,MATCH(Datas!A16&Datas!C16&Datas!D16,Datas!$A$2:$A$336&Datas!$C$2:$C$336&Datas!$D$2:$D$336,0)),"DDD")} -> seg | R26: =S26+U26 -> 0 | S26: =IFERROR(T26-W26,0) -> 0 | T26: =IF(AND(D26>=$Y$14,D26<=$Y$15),$Y$15,IF(AND(D26>=$Y$12,D26<=$Y$13),$Y$12,0)) -> 0 | U26: =IFERROR(X26-V26,0) -> 0 | V26: =IF(AND(I26>=$Y$14,I26<=$Y$15),$Y$15,IF(AND(I26>=$Y$12,I26<=$Y$13),$Y$12,0)) -> 0 | W26: =IF(AND($D26>=$Y$12,$D26<=$Y$13),$D26,IF(AND($D26>=$Y$14,$D26<=$Y$15),$D26,0)) -> 0 | X26: =IF(AND($I26>=$Y$12,$I26<=$Y$13),$I26,IF(AND($I26>=$Y$14,$I26<=$Y$15),$I26,0)) -> 0
A27: =A26+1 -> 44356 | B27: =VLOOKUP($A27,Datas!$B:$E,4,0) -> #N/A | C27: {=TEXT(INDEX($A$12:$A$41,MATCH(Datas!A17&Datas!C17&Datas!D17,Datas!$A$2:$A$336&Datas!$C$2:$C$336&Datas!$D$2:$D$336,0)),"DDD")} -> ter | R27: =S27+U27 -> 0 | S27: =IFERROR(T27-W27,0) -> 0 | T27: =IF(AND(D27>=$Y$14,D27<=$Y$15),$Y$15,IF(AND(D27>=$Y$12,D27<=$Y$13),$Y$12,0)) -> 0 | U27: =IFERROR(X27-V27,0) -> 0 | V27: =IF(AND(I27>=$Y$14,I27<=$Y$15),$Y$15,IF(AND(I27>=$Y$12,I27<=$Y$13),$Y$12,0)) -> 0 | W27: =IF(AND($D27>=$Y$12,$D27<=$Y$13),$D27,IF(AND($D27>=$Y$14,$D27<=$Y$15),$D27,0)) -> 0 | X27: =IF(AND($I27>=$Y$12,$I27<=$Y$13),$I27,IF(AND($I27>=$Y$14,$I27<=$Y$15),$I27,0)) -> 0
A28: =A27+1 -> 44357 | B28: =VLOOKUP($A28,Datas!$B:$E,4,0) -> #N/A | C28: {=TEXT(INDEX($A$12:$A$41,MATCH(Datas!A18&Datas!C18&Datas!D18,Datas!$A$2:$A$336&Datas!$C$2:$C$336&Datas!$D$2:$D$336,0)),"DDD")} -> qua | R28: =S28+U28 -> 0 | S28: =IFERROR(T28-W28,0) -> 0 | T28: =IF(AND(D28>=$Y$14,D28<=$Y$15),$Y$15,IF(AND(D28>=$Y$12,D28<=$Y$13),$Y$12,0)) -> 0 | U28: =IFERROR(X28-V28,0) -> 0 | V28: =IF(AND(I28>=$Y$14,I28<=$Y$15),$Y$15,IF(AND(I28>=$Y$12,I28<=$Y$13),$Y$12,0)) -> 0 | W28: =IF(AND($D28>=$Y$12,$D28<=$Y$13),$D28,IF(AND($D28>=$Y$14,$D28<=$Y$15),$D28,0)) -> 0 | X28: =IF(AND($I28>=$Y$12,$I28<=$Y$13),$I28,IF(AND($I28>=$Y$14,$I28<=$Y$15),$I28,0)) -> 0
A29: =A28+1 -> 44358 | B29: =VLOOKUP($A29,Datas!$B:$E,4,0) -> #N/A | C29: {=TEXT(INDEX($A$12:$A$41,MATCH(Datas!A19&Datas!C19&Datas!D19,Datas!$A$2:$A$336&Datas!$C$2:$C$336&Datas!$D$2:$D$336,0)),"DDD")} -> qui | R29: =S29+U29 -> 0 | S29: =IFERROR(T29-W29,0) -> 0 | T29: =IF(AND(D29>=$Y$14,D29<=$Y$15),$Y$15,IF(AND(D29>=$Y$12,D29<=$Y$13),$Y$12,0)) -> 0 | U29: =IFERROR(X29-V29,0) -> 0 | V29: =IF(AND(I29>=$Y$14,I29<=$Y$15),$Y$15,IF(AND(I29>=$Y$12,I29<=$Y$13),$Y$12,0)) -> 0 | W29: =IF(AND($D29>=$Y$12,$D29<=$Y$13),$D29,IF(AND($D29>=$Y$14,$D29<=$Y$15),$D29,0)) -> 0 | X29: =IF(AND($I29>=$Y$12,$I29<=$Y$13),$I29,IF(AND($I29>=$Y$14,$I29<=$Y$15),$I29,0)) -> 0
A30: =A29+1 -> 44359 | B30: =VLOOKUP($A30,Datas!$B:$E,4,0) -> #N/A | C30: {=TEXT(INDEX($A$12:$A$41,MATCH(Datas!A20&Datas!C20&Datas!D20,Datas!$A$2:$A$336&Datas!$C$2:$C$336&Datas!$D$2:$D$336,0)),"DDD")} -> sex | R30: =S30+U30 -> 0 | S30: =IFERROR(T30-W30,0) -> 0 | T30: =IF(AND(D30>=$Y$14,D30<=$Y$15),$Y$15,IF(AND(D30>=$Y$12,D30<=$Y$13),$Y$12,0)) -> 0 | U30: =IFERROR(X30-V30,0) -> 0 | V30: =IF(AND(I30>=$Y$14,I30<=$Y$15),$Y$15,IF(AND(I30>=$Y$12,I30<=$Y$13),$Y$12,0)) -> 0 | W30: =IF(AND($D30>=$Y$12,$D30<=$Y$13),$D30,IF(AND($D30>=$Y$14,$D30<=$Y$15),$D30,0)) -> 0 | X30: =IF(AND($I30>=$Y$12,$I30<=$Y$13),$I30,IF(AND($I30>=$Y$14,$I30<=$Y$15),$I30,0)) -> 0
A31: =A30+1 -> 44360 | B31: =VLOOKUP($A31,Datas!$B:$E,4,0) -> #N/A | C31: {=TEXT(INDEX($A$12:$A$41,MATCH(Datas!A21&Datas!C21&Datas!D21,Datas!$A$2:$A$336&Datas!$C$2:$C$336&Datas!$D$2:$D$336,0)),"DDD")} -> sáb | R31: =S31+U31 -> 0 | S31: =IFERROR(T31-W31,0) -> 0 | T31: =IF(AND(D31>=$Y$14,D31<=$Y$15),$Y$15,IF(AND(D31>=$Y$12,D31<=$Y$13),$Y$12,0)) -> 0 | U31: =IFERROR(X31-V31,0) -> 0 | V31: =IF(AND(I31>=$Y$14,I31<=$Y$15),$Y$15,IF(AND(I31>=$Y$12,I31<=$Y$13),$Y$12,0)) -> 0 | W31: =IF(AND($D31>=$Y$12,$D31<=$Y$13),$D31,IF(AND($D31>=$Y$14,$D31<=$Y$15),$D31,0)) -> 0 | X31: =IF(AND($I31>=$Y$12,$I31<=$Y$13),$I31,IF(AND($I31>=$Y$14,$I31<=$Y$15),$I31,0)) -> 0
A32: =A31+1 -> 44361 | B32: =VLOOKUP($A32,Datas!$B:$E,4,0) -> #N/A | C32: {=TEXT(INDEX($A$12:$A$41,MATCH(Datas!A22&Datas!C22&Datas!D22,Datas!$A$2:$A$336&Datas!$C$2:$C$336&Datas!$D$2:$D$336,0)),"DDD")} -> dom | R32: =S32+U32 -> 0 | S32: =IFERROR(T32-W32,0) -> 0 | T32: =IF(AND(D32>=$Y$14,D32<=$Y$15),$Y$15,IF(AND(D32>=$Y$12,D32<=$Y$13),$Y$12,0)) -> 0 | U32: =IFERROR(X32-V32,0) -> 0 | V32: =IF(AND(I32>=$Y$14,I32<=$Y$15),$Y$15,IF(AND(I32>=$Y$12,I32<=$Y$13),$Y$12,0)) -> 0 | W32: =IF(AND($D32>=$Y$12,$D32<=$Y$13),$D32,IF(AND($D32>=$Y$14,$D32<=$Y$15),$D32,0)) -> 0 | X32: =IF(AND($I32>=$Y$12,$I32<=$Y$13),$I32,IF(AND($I32>=$Y$14,$I32<=$Y$15),$I32,0)) -> 0
A33: =A32+1 -> 44362 | B33: =VLOOKUP($A33,Datas!$B:$E,4,0) -> #N/A | C33: {=TEXT(INDEX($A$12:$A$41,MATCH(Datas!A23&Datas!C23&Datas!D23,Datas!$A$2:$A$336&Datas!$C$2:$C$336&Datas!$D$2:$D$336,0)),"DDD")} -> seg | R33: =S33+U33 -> 0 | S33: =IFERROR(T33-W33,0) -> 0 | T33: =IF(AND(D33>=$Y$14,D33<=$Y$15),$Y$15,IF(AND(D33>=$Y$12,D33<=$Y$13),$Y$12,0)) -> 0 | U33: =IFERROR(X33-V33,0) -> 0 | V33: =IF(AND(I33>=$Y$14,I33<=$Y$15),$Y$15,IF(AND(I33>=$Y$12,I33<=$Y$13),$Y$12,0)) -> 0 | W33: =IF(AND($D33>=$Y$12,$D33<=$Y$13),$D33,IF(AND($D33>=$Y$14,$D33<=$Y$15),$D33,0)) -> 0 | X33: =IF(AND($I33>=$Y$12,$I33<=$Y$13),$I33,IF(AND($I33>=$Y$14,$I33<=$Y$15),$I33,0)) -> 0
A34: =A33+1 -> 44363 | B34: =VLOOKUP($A34,Datas!$B:$E,4,0) -> #N/A | C34: {=TEXT(INDEX($A$12:$A$41,MATCH(Datas!A24&Datas!C24&Datas!D24,Datas!$A$2:$A$336&Datas!$C$2:$C$336&Datas!$D$2:$D$336,0)),"DDD")} -> ter | R34: =S34+U34 -> 0 | S34: =IFERROR(T34-W34,0) -> 0 | T34: =IF(AND(D34>=$Y$14,D34<=$Y$15),$Y$15,IF(AND(D34>=$Y$12,D34<=$Y$13),$Y$12,0)) -> 0 | U34: =IFERROR(X34-V34,0) -> 0 | V34: =IF(AND(I34>=$Y$14,I34<=$Y$15),$Y$15,IF(AND(I34>=$Y$12,I34<=$Y$13),$Y$12,0)) -> 0 | W34: =IF(AND($D34>=$Y$12,$D34<=$Y$13),$D34,IF(AND($D34>=$Y$14,$D34<=$Y$15),$D34,0)) -> 0 | X34: =IF(AND($I34>=$Y$12,$I34<=$Y$13),$I34,IF(AND($I34>=$Y$14,$I34<=$Y$15),$I34,0)) -> 0
A35: =A34+1 -> 44364 | B35: =VLOOKUP($A35,Datas!$B:$E,4,0) -> #N/A | C35: {=TEXT(INDEX($A$12:$A$41,MATCH(Datas!A25&Datas!C25&Datas!D25,Datas!$A$2:$A$336&Datas!$C$2:$C$336&Datas!$D$2:$D$336,0)),"DDD")} -> qua | R35: =S35+U35 -> 0 | S35: =IFERROR(T35-W35,0) -> 0 | T35: =IF(AND(D35>=$Y$14,D35<=$Y$15),$Y$15,IF(AND(D35>=$Y$12,D35<=$Y$13),$Y$12,0)) -> 0 | U35: =IFERROR(X35-V35,0) -> 0 | V35: =IF(AND(I35>=$Y$14,I35<=$Y$15),$Y$15,IF(AND(I35>=$Y$12,I35<=$Y$13),$Y$12,0)) -> 0 | W35: =IF(AND($D35>=$Y$12,$D35<=$Y$13),$D35,IF(AND($D35>=$Y$14,$D35<=$Y$15),$D35,0)) -> 0 | X35: =IF(AND($I35>=$Y$12,$I35<=$Y$13),$I35,IF(AND($I35>=$Y$14,$I35<=$Y$15),$I35,0)) -> 0 | AA35: calc
A36: =A35+1 -> 44365 | B36: =VLOOKUP($A36,Datas!$B:$E,4,0) -> #N/A | C36: {=TEXT(INDEX($A$12:$A$41,MATCH(Datas!A26&Datas!C26&Datas!D26,Datas!$A$2:$A$336&Datas!$C$2:$C$336&Datas!$D$2:$D$336,0)),"DDD")} -> qui | R36: =S36+U36 -> 0 | S36: =IFERROR(T36-W36,0) -> 0 | T36: =IF(AND(D36>=$Y$14,D36<=$Y$15),$Y$15,IF(AND(D36>=$Y$12,D36<=$Y$13),$Y$12,0)) -> 0 | U36: =IFERROR(X36-V36,0) -> 0 | V36: =IF(AND(I36>=$Y$14,I36<=$Y$15),$Y$15,IF(AND(I36>=$Y$12,I36<=$Y$13),$Y$12,0)) -> 0 | W36: =IF(AND($D36>=$Y$12,$D36<=$Y$13),$D36,IF(AND($D36>=$Y$14,$D36<=$Y$15),$D36,0)) -> 0 | X36: =IF(AND($I36>=$Y$12,$I36<=$Y$13),$I36,IF(AND($I36>=$Y$14,$I36<=$Y$15),$I36,0)) -> 0
A37: =A36+1 -> 44366 | B37: =VLOOKUP($A37,Datas!$B:$E,4,0) -> #N/A | C37: {=TEXT(INDEX($A$12:$A$41,MATCH(Datas!A27&Datas!C27&Datas!D27,Datas!$A$2:$A$336&Datas!$C$2:$C$336&Datas!$D$2:$D$336,0)),"DDD")} -> sex | R37: =S37+U37 -> 0 | S37: =IFERROR(T37-W37,0) -> 0 | T37: =IF(AND(D37>=$Y$14,D37<=$Y$15),$Y$15,IF(AND(D37>=$Y$12,D37<=$Y$13),$Y$12,0)) -> 0 | U37: =IFERROR(X37-V37,0) -> 0 | V37: =IF(AND(I37>=$Y$14,I37<=$Y$15),$Y$15,IF(AND(I37>=$Y$12,I37<=$Y$13),$Y$12,0)) -> 0 | W37: =IF(AND($D37>=$Y$12,$D37<=$Y$13),$D37,IF(AND($D37>=$Y$14,$D37<=$Y$15),$D37,0)) -> 0 | X37: =IF(AND($I37>=$Y$12,$I37<=$Y$13),$I37,IF(AND($I37>=$Y$14,$I37<=$Y$15),$I37,0)) -> 0
A38: =A37+1 -> 44367 | B38: =VLOOKUP($A38,Datas!$B:$E,4,0) -> #N/A | C38: {=TEXT(INDEX($A$12:$A$41,MATCH(Datas!A28&Datas!C28&Datas!D28,Datas!$A$2:$A$336&Datas!$C$2:$C$336&Datas!$D$2:$D$336,0)),"DDD")} -> sáb | R38: =S38+U38 -> 0 | S38: =IFERROR(T38-W38,0) -> 0 | T38: =IF(AND(D38>=$Y$14,D38<=$Y$15),$Y$15,IF(AND(D38>=$Y$12,D38<=$Y$13),$Y$12,0)) -> 0 | U38: =IFERROR(X38-V38,0) -> 0 | V38: =IF(AND(I38>=$Y$14,I38<=$Y$15),$Y$15,IF(AND(I38>=$Y$12,I38<=$Y$13),$Y$12,0)) -> 0 | W38: =IF(AND($D38>=$Y$12,$D38<=$Y$13),$D38,IF(AND($D38>=$Y$14,$D38<=$Y$15),$D38,0)) -> 0 | X38: =IF(AND($I38>=$Y$12,$I38<=$Y$13),$I38,IF(AND($I38>=$Y$14,$I38<=$Y$15),$I38,0)) -> 0
A39: =A38+1 -> 44368 | B39: =VLOOKUP($A39,Datas!$B:$E,4,0) -> #N/A | C39: {=TEXT(INDEX($A$12:$A$41,MATCH(Datas!A29&Datas!C29&Datas!D29,Datas!$A$2:$A$336&Datas!$C$2:$C$336&Datas!$D$2:$D$336,0)),"DDD")} -> dom | R39: =S39+U39 -> 0 | S39: =IFERROR(T39-W39,0) -> 0 | T39: =IF(AND(D39>=$Y$14,D39<=$Y$15),$Y$15,IF(AND(D39>=$Y$12,D39<=$Y$13),$Y$12,0)) -> 0 | U39: =IFERROR(X39-V39,0) -> 0 | V39: =IF(AND(I39>=$Y$14,I39<=$Y$15),$Y$15,IF(AND(I39>=$Y$12,I39<=$Y$13),$Y$12,0)) -> 0 | W39: =IF(AND($D39>=$Y$12,$D39<=$Y$13),$D39,IF(AND($D39>=$Y$14,$D39<=$Y$15),$D39,0)) -> 0 | X39: =IF(AND($I39>=$Y$12,$I39<=$Y$13),$I39,IF(AND($I39>=$Y$14,$I39<=$Y$15),$I39,0)) -> 0
A40: =A39+1 -> 44369 | B40: =VLOOKUP($A40,Datas!$B:$E,4,0) -> #N/A | C40: {=TEXT(INDEX($A$12:$A$41,MATCH(Datas!A30&Datas!C30&Datas!D30,Datas!$A$2:$A$336&Datas!$C$2:$C$336&Datas!$D$2:$D$336,0)),"DDD")} -> seg | R40: =S40+U40 -> 0 | S40: =IFERROR(T40-W40,0) -> 0 | T40: =IF(AND(D40>=$Y$14,D40<=$Y$15),$Y$15,IF(AND(D40>=$Y$12,D40<=$Y$13),$Y$12,0)) -> 0 | U40: =IFERROR(X40-V40,0) -> 0 | V40: =IF(AND(I40>=$Y$14,I40<=$Y$15),$Y$15,IF(AND(I40>=$Y$12,I40<=$Y$13),$Y$12,0)) -> 0 | W40: =IF(AND($D40>=$Y$12,$D40<=$Y$13),$D40,IF(AND($D40>=$Y$14,$D40<=$Y$15),$D40,0)) -> 0 | X40: =IF(AND($I40>=$Y$12,$I40<=$Y$13),$I40,IF(AND($I40>=$Y$14,$I40<=$Y$15),$I40,0)) -> 0
A41: =A40+1 -> 44370 | B41: =VLOOKUP($A41,Datas!$B:$E,4,0) -> #N/A | C41: {=TEXT(INDEX($A$12:$A$41,MATCH(Datas!A31&Datas!C31&Datas!D31,Datas!$A$2:$A$336&Datas!$C$2:$C$336&Datas!$D$2:$D$336,0)),"DDD")} -> ter | R41: =S41+U41 -> 0 | S41: =IFERROR(T41-W41,0) -> 0 | T41: =IF(AND(D41>=$Y$14,D41<=$Y$15),$Y$15,IF(AND(D41>=$Y$12,D41<=$Y$13),$Y$12,0)) -> 0 | U41: =IFERROR(X41-V41,0) -> 0 | V41: =IF(AND(I41>=$Y$14,I41<=$Y$15),$Y$15,IF(AND(I41>=$Y$12,I41<=$Y$13),$Y$12,0)) -> 0 | W41: =IF(AND($D41>=$Y$12,$D41<=$Y$13),$D41,IF(AND($D41>=$Y$14,$D41<=$Y$15),$D41,0)) -> 0 | X41: =IF(AND($I41>=$Y$12,$I41<=$Y$13),$I41,IF(AND($I41>=$Y$14,$I41<=$Y$15),$I41,0)) -> 0
...

Sheet FOLHA OP 02
D1: EMPRESA: | Z1: Horário de Trabalho Interno | AA1: 0.75 | AB1: 0.00069444444 | AC1: Urbana 2 | AD1: 0.75
AA2: 38 | AC2: Urbana | AD2: 0.74930556
D3: ENDEREÇO: | L3: 02301-110 | Z3: Ficha Individual - Art 74/3 CLT | AA3: 0 | AC3: Folga | AD3: 0
D4: BAIRRO: | L4: SÃO PAULO | M4: UF: | N4: SP | Z4: Portaria Nº 3082 de 11/04/98
D5: CODIGO: 0000 | F5: NOME
Z6: MÊS
D7: CARGO : VIGILANTE DE ESCOLTA ARMADA | R7: RODOVIÁRIO | S7: 38 | Z7: 44316
D8: DEPTO/ SETOR/ SEÇÃO: 0001/ 0002 / 0000 | R8: URBANO | S8: 38
A10: DATA | C10: DIA | D10: ENTRADA | E10: REFEIÇÃO (ALMOÇO) | G10: REFEIÇÃO (JANTAR) | I10: SAÍDA | J10: Horas Desconto | K10: T. H Corrida | L10: AD. NOT. | M10: AJ. CUSTO | N10: ASS. FUNCIONÁRIO | Z10: OBSERVAÇÕES
E11: SAÍDA | F11: ENTRADA | G11: SAÍDA | H11: ENTRADA | R11: SOMA AD. NOT | S11: RESULTADO ENTRADA | T11: REFERENCIA ENTRADA | U11: RESULTADO SAIDA | V11: REFERENCIA SAIDA | W11: CONDIÇÃO DE SOMA ENTRADA | X11: CONDIÇÃO DE SOMA SAIDA | Y11: REFERENCIA HORAS EM NUMEROS | AB11: Q1 | AC11: =COUNTIF(#REF!,$AA$2) -> #REF! | AD11: =SUM(#REF!) -> #REF!
A12: 44341 | B12: =VLOOKUP($A12,Datas!$B:$E,4,0) -> #N/A | C12: {=TEXT(INDEX($A$12:$A$41,MATCH(Datas!A2&Datas!C2&Datas!D2,Datas!$A$2:$A$336&Datas!$C$2:$C$336&Datas!$D$2:$D$336,0)),"DDD")} -> seg | J12: =IFERROR((E12-D12)+(G12-F12)+(I12-H12)-#REF!,0) -> 0 | K12: 0 | L12: =R12 -> 0 | M12: =IF(J12>=0.01,9,0) -> 0 | R12: =S12+U12 -> 0 | S12: =IFERROR(T12-W12,0) -> 0 | T12: =IF(AND(D12>=$Y$14,D12<=$Y$15),$Y$15,IF(AND(D12>=$Y$12,D12<=$Y$13),$Y$12,0)) -> 0 | U12: =IFERROR(X12-V12,0) -> 0 | V12: =IF(AND(I12>=$Y$14,I12<=$Y$15),$Y$15,IF(AND(I12>=$Y$12,I12<=$Y$13),$Y$12,0)) -> 0 | W12: =IF(AND($D12>=$Y$12,$D12<=$Y$13),$D12,IF(AND($D12>=$Y$14,$D12<=$Y$15),$D12,0)) -> 0 | X12: =IF(AND($I12>=$Y$12,$I12<=$Y$13),$I12,IF(AND($I12>=$Y$14,$I12<=$Y$15),$I12,0)) -> 0 | Y12: 0.91666667 | AB12: Q2 | AC12: =COUNTIF(#REF!,$AA$2) -> #REF! | AD12: =SUM(#REF!) -> #REF!
A13: =A12+1 -> 44342 | B13: =VLOOKUP($A13,Datas!$B:$E,4,0) -> #N/A | C13: {=TEXT(INDEX($A$12:$A$41,MATCH(Datas!A3&Datas!C3&Datas!D3,Datas!$A$2:$A$336&Datas!$C$2:$C$336&Datas!$D$2:$D$336,0)),"DDD")} -> ter | J13: =IFERROR((E13-D13)+(G13-F13)+(I13-H13)-#REF!,0) -> 0 | K13: 0.29166667 | L13: 0.25 | M13: 9 | R13: =S13+U13 -> 0 | S13: =IFERROR(T13-W13,0) -> 0 | T13: =IF(AND(D13>=$Y$14,D13<=$Y$15),$Y$15,IF(AND(D13>=$Y$12,D13<=$Y$13),$Y$12,0)) -> 0 | U13: =IFERROR(X13-V13,0) -> 0 | V13: =IF(AND(I13>=$Y$14,I13<=$Y$15),$Y$15,IF(AND(I13>=$Y$12,I13<=$Y$13),$Y$12,0)) -> 0 | W13: =IF(AND($D13>=$Y$12,$D13<=$Y$13),$D13,IF(AND($D13>=$Y$14,$D13<=$Y$15),$D13,0)) -> 0 | X13: =IF(AND($I13>=$Y$12,$I13<=$Y$13),$I13,IF(AND($I13>=$Y$14,$I13<=$Y$15),$I13,0)) -> 0 | Y13: 0.99930556
A14: =A13+1 -> 44343 | B14: =VLOOKUP($A14,Datas!$B:$E,4,0) -> #N/A | C14: {=TEXT(INDEX($A$12:$A$41,MATCH(Datas!A4&Datas!C4&Datas!D4,Datas!$A$2:$A$336&Datas!$C$2:$C$336&Datas!$D$2:$D$336,0)),"DDD")} -> qua | J14: =IFERROR((E14-D14)+(G14-F14)+(I14-H14)-#REF!,0) -> 0 | K14: 0.5 | L14: 0.29166667 | M14: 9 | R14: =S14+U14 -> 0 | S14: =IFERROR(T14-W14,0) -> 0 | T14: =IF(AND(D14>=$Y$14,D14<=$Y$15),$Y$15,IF(AND(D14>=$Y$12,D14<=$Y$13),$Y$12,0)) -> 0 | U14: =IFERROR(X14-V14,0) -> 0 | V14: =IF(AND(I14>=$Y$14,I14<=$Y$15),$Y$15,IF(AND(I14>=$Y$12,I14<=$Y$13),$Y$12,0)) -> 0 | W14: =IF(AND($D14>=$Y$12,$D14<=$Y$13),$D14,IF(AND($D14>=$Y$14,$D14<=$Y$15),$D14,0)) -> 0 | X14: =IF(AND($I14>=$Y$12,$I14<=$Y$13),$I14,IF(AND($I14>=$Y$14,$I14<=$Y$15),$I14,0)) -> 0 | Y14: 0.00069444444
A15: =A14+1 -> 44344 | B15: =VLOOKUP($A15,Datas!$B:$E,4,0) -> #N/A | C15: {=TEXT(INDEX($A$12:$A$41,MATCH(Datas!A5&Datas!C5&Datas!D5,Datas!$A$2:$A$336&Datas!$C$2:$C$336&Datas!$D$2:$D$336,0)),"DDD")} -> qui | J15: =IFERROR((E15-D15)+(G15-F15)+(I15-H15)-#REF!,0) -> 0 | K15: 0.5 | L15: 0.29166667 | M15: 9 | R15: =S15+U15 -> 0 | S15: =IFERROR(T15-W15,0) -> 0 | T15: =IF(AND(D15>=$Y$14,D15<=$Y$15),$Y$15,IF(AND(D15>=$Y$12,D15<=$Y$13),$Y$12,0)) -> 0 | U15: =IFERROR(X15-V15,0) -> 0 | V15: =IF(AND(I15>=$Y$14,I15<=$Y$15),$Y$15,IF(AND(I15>=$Y$12,I15<=$Y$13),$Y$12,0)) -> 0 | W15: =IF(AND($D15>=$Y$12,$D15<=$Y$13),$D15,IF(AND($D15>=$Y$14,$D15<=$Y$15),$D15,0)) -> 0 | X15: =IF(AND($I15>=$Y$12,$I15<=$Y$13),$I15,IF(AND($I15>=$Y$14,$I15<=$Y$15),$I15,0)) -> 0 | Y15: 0.20833333
A16: =A15+1 -> 44345 | B16: =VLOOKUP($A16,Datas!$B:$E,4,0) -> #N/A | C16: {=TEXT(INDEX($A$12:$A$41,MATCH(Datas!A6&Datas!C6&Datas!D6,Datas!$A$2:$A$336&Datas!$C$2:$C$336&Datas!$D$2:$D$336,0)),"DDD")} -> sex | J16: =IFERROR((E16-D16)+(G16-F16)+(I16-H16)-#REF!,0) -> 0 | K16: 0.30555556 | L16: 0.18055556 | M16: =IF(J16>=0.01,9,0) -> 0 | R16: =S16+U16 -> 0 | S16: =IFERROR(T16-W16,0) -> 0 | T16: =IF(AND(D16>=$Y$14,D16<=$Y$15),$Y$15,IF(AND(D16>=$Y$12,D16<=$Y$13),$Y$12,0)) -> 0 | U16: =IFERROR(X16-V16,0) -> 0 | V16: =IF(AND(I16>=$Y$14,I16<=$Y$15),$Y$15,IF(AND(I16>=$Y$12,I16<=$Y$13),$Y$12,0)) -> 0 | W16: =IF(AND($D16>=$Y$12,$D16<=$Y$13),$D16,IF(AND($D16>=$Y$14,$D16<=$Y$15),$D16,0)) -> 0 | X16: =IF(AND($I16>=$Y$12,$I16<=$Y$13),$I16,IF(AND($I16>=$Y$14,$I16<=$Y$15),$I16,0)) -> 0
A17: =A16+1 -> 44346 | B17: =VLOOKUP($A17,Datas!$B:$E,4,0) -> #N/A | C17: {=TEXT(INDEX($A$12:$A$41,MATCH(Datas!A7&Datas!C7&Datas!D7,Datas!$A$2:$A$336&Datas!$C$2:$C$336&Datas!$D$2:$D$336,0)),"DDD")} -> sáb | J17: =IFERROR((E17-D17)+(G17-F17)+(I17-H17)-#REF!,0) -> 0 | K17: 0.29166667 | L17: 0.25 | M17: 9 | R17: =S17+U17 -> 0 | S17: =IFERROR(T17-W17,0) -> 0 | T17: =IF(AND(D17>=$Y$14,D17<=$Y$15),$Y$15,IF(AND(D17>=$Y$12,D17<=$Y$13),$Y$12,0)) -> 0 | U17: =IFERROR(X17-V17,0) -> 0 | V17: =IF(AND(I17>=$Y$14,I17<=$Y$15),$Y$15,IF(AND(I17>=$Y$12,I17<=$Y$13),$Y$12,0)) -> 0 | W17: =IF(AND($D17>=$Y$12,$D17<=$Y$13),$D17,IF(AND($D17>=$Y$14,$D17<=$Y$15),$D17,0)) -> 0 | X17: =IF(AND($I17>=$Y$12,$I17<=$Y$13),$I17,IF(AND($I17>=$Y$14,$I17<=$Y$15),$I17,0)) -> 0
A18: =A17+1 -> 44347 | B18: =VLOOKUP($A18,Datas!$B:$E,4,0) -> #N/A | C18: {=TEXT(INDEX($A$12:$A$41,MATCH(Datas!A8&Datas!C8&Datas!D8,Datas!$A$2:$A$336&Datas!$C$2:$C$336&Datas!$D$2:$D$336,0)),"DDD")} -> dom | J18: =IFERROR((E18-D18)+(G18-F18)+(I18-H18)-#REF!,0) -> 0 | K18: 0.5 | L18: 0.29166667 | M18: 9 | R18: =S18+U18 -> 0 | S18: =IFERROR(T18-W18,0) -> 0 | T18: =IF(AND(D18>=$Y$14,D18<=$Y$15),$Y$15,IF(AND(D18>=$Y$12,D18<=$Y$13),$Y$12,0)) -> 0 | U18: =IFERROR(X18-V18,0) -> 0 | V18: =IF(AND(I18>=$Y$14,I18<=$Y$15),$Y$15,IF(AND(I18>=$Y$12,I18<=$Y$13),$Y$12,0)) -> 0 | W18: =IF(AND($D18>=$Y$12,$D18<=$Y$13),$D18,IF(AND($D18>=$Y$14,$D18<=$Y$15),$D18,0)) -> 0 | X18: =IF(AND($I18>=$Y$12,$I18<=$Y$13),$I18,IF(AND($I18>=$Y$14,$I18<=$Y$15),$I18,0)) -> 0
A19: =A18+1 -> 44348 | B19: =VLOOKUP($A19,Datas!$B:$E,4,0) -> #N/A | C19: {=TEXT(INDEX($A$12:$A$41,MATCH(Datas!A9&Datas!C9&Datas!D9,Datas!$A$2:$A$336&Datas!$C$2:$C$336&Datas!$D$2:$D$336,0)),"DDD")} -> seg | J19: =IFERROR((E19-D19)+(G19-F19)+(I19-H19)-#REF!,0) -> 0 | K19: 0 | L19: =R19 -> 0 | M19: =IF(J19>=0.01,9,0) -> 0 | R19: =S19+U19 -> 0 | S19: =IFERROR(T19-W19,0) -> 0 | T19: =IF(AND(D19>=$Y$14,D19<=$Y$15),$Y$15,IF(AND(D19>=$Y$12,D19<=$Y$13),$Y$12,0)) -> 0 | U19: =IFERROR(X19-V19,0) -> 0 | V19: =IF(AND(I19>=$Y$14,I19<=$Y$15),$Y$15,IF(AND(I19>=$Y$12,I19<=$Y$13),$Y$12,0)) -> 0 | W19: =IF(AND($D19>=$Y$12,$D19<=$Y$13),$D19,IF(AND($D19>=$Y$14,$D19<=$Y$15),$D19,0)) -> 0 | X19: =IF(AND($I19>=$Y$12,$I19<=$Y$13),$I19,IF(AND($I19>=$Y$14,$I19<=$Y$15),$I19,0)) -> 0
A20: =A19+1 -> 44349 | B20: =VLOOKUP($A20,Datas!$B:$E,4,0) -> #N/A | C20: {=TEXT(INDEX($A$12:$A$41,MATCH(Datas!A10&Datas!C10&Datas!D10,Datas!$A$2:$A$336&Datas!$C$2:$C$336&Datas!$D$2:$D$336,0)),"DDD")} -> ter | J20: =IFERROR((E20-D20)+(G20-F20)+(I20-H20)-#REF!,0) -> 0 | K20: 0.29166667 | L20: 0.25 | M20: 9 | R20: =S20+U20 -> 0 | S20: =IFERROR(T20-W20,0) -> 0 | T20: =IF(AND(D20>=$Y$14,D20<=$Y$15),$Y$15,IF(AND(D20>=$Y$12,D20<=$Y$13),$Y$12,0)) -> 0 | U20: =IFERROR(X20-V20,0) -> 0 | V20: =IF(AND(I20>=$Y$14,I20<=$Y$15),$Y$15,IF(AND(I20>=$Y$12,I20<=$Y$13),$Y$12,0)) -> 0 | W20: =IF(AND($D20>=$Y$12,$D20<=$Y$13),$D20,IF(AND($D20>=$Y$14,$D20<=$Y$15),$D20,0)) -> 0 | X20: =IF(AND($I20>=$Y$12,$I20<=$Y$13),$I20,IF(AND($I20>=$Y$14,$I20<=$Y$15),$I20,0)) -> 0
A21: =A20+1 -> 44350 | B21: =VLOOKUP($A21,Datas!$B:$E,4,0) -> #N/A | C21: {=TEXT(INDEX($A$12:$A$41,MATCH(Datas!A11&Datas!C11&Datas!D11,Datas!$A$2:$A$336&Datas!$C$2:$C$336&Datas!$D$2:$D$336,0)),"DDD")} -> qua | J21: =IFERROR((E21-D21)+(G21-F21)+(I21-H21)-#REF!,0) -> 0 | K21: 0.5 | L21: 0.29166667 | M21: 9 | R21: =S21+U21 -> 0 | S21: =IFERROR(T21-W21,0) -> 0 | T21: =IF(AND(D21>=$Y$14,D21<=$Y$15),$Y$15,IF(AND(D21>=$Y$12,D21<=$Y$13),$Y$12,0)) -> 0 | U21: =IFERROR(X21-V21,0) -> 0 | V21: =IF(AND(I21>=$Y$14,I21<=$Y$15),$Y$15,IF(AND(I21>=$Y$12,I21<=$Y$13),$Y$12,0)) -> 0 | W21: =IF(AND($D21>=$Y$12,$D21<=$Y$13),$D21,IF(AND($D21>=$Y$14,$D21<=$Y$15),$D21,0)) -> 0 | X21: =IF(AND($I21>=$Y$12,$I21<=$Y$13),$I21,IF(AND($I21>=$Y$14,$I21<=$Y$15),$I21,0)) -> 0
A22: =A21+1 -> 44351 | B22: =VLOOKUP($A22,Datas!$B:$E,4,0) -> #N/A | C22: {=TEXT(INDEX($A$12:$A$41,MATCH(Datas!A12&Datas!C12&Datas!D12,Datas!$A$2:$A$336&Datas!$C$2:$C$336&Datas!$D$2:$D$336,0)),"DDD")} -> qui | J22: =IFERROR((E22-D22)+(G22-F22)+(I22-H22)-#REF!,0) -> 0 | K22: 0.5 | L22: 0.29166667 | M22: 9 | R22: =S22+U22 -> 0 | S22: =IFERROR(T22-W22,0) -> 0 | T22: =IF(AND(D22>=$Y$14,D22<=$Y$15),$Y$15,IF(AND(D22>=$Y$12,D22<=$Y$13),$Y$12,0)) -> 0 | U22: =IFERROR(X22-V22,0) -> 0 | V22: =IF(AND(I22>=$Y$14,I22<=$Y$15),$Y$15,IF(AND(I22>=$Y$12,I22<=$Y$13),$Y$12,0)) -> 0 | W22: =IF(AND($D22>=$Y$12,$D22<=$Y$13),$D22,IF(AND($D22>=$Y$14,$D22<=$Y$15),$D22,0)) -> 0 | X22: =IF(AND($I22>=$Y$12,$I22<=$Y$13),$I22,IF(AND($I22>=$Y$14,$I22<=$Y$15),$I22,0)) -> 0
A23: =A22+1 -> 44352 | B23: =VLOOKUP($A23,Datas!$B:$E,4,0) -> #N/A | C23: {=TEXT(INDEX($A$12:$A$41,MATCH(Datas!A13&Datas!C13&Datas!D13,Datas!$A$2:$A$336&Datas!$C$2:$C$336&Datas!$D$2:$D$336,0)),"DDD")} -> sex | J23: =IFERROR((E23-D23)+(G23-F23)+(I23-H23)-#REF!,0) -> 0 | K23: 0.5 | L23: 0.29166667 | M23: 9 | R23: =S23+U23 -> 0 | S23: =IFERROR(T23-W23,0) -> 0 | T23: =IF(AND(D23>=$Y$14,D23<=$Y$15),$Y$15,IF(AND(D23>=$Y$12,D23<=$Y$13),$Y$12,0)) -> 0 | U23: =IFERROR(X23-V23,0) -> 0 | V23: =IF(AND(I23>=$Y$14,I23<=$Y$15),$Y$15,IF(AND(I23>=$Y$12,I23<=$Y$13),$Y$12,0)) -> 0 | W23: =IF(AND($D23>=$Y$12,$D23<=$Y$13),$D23,IF(AND($D23>=$Y$14,$D23<=$Y$15),$D23,0)) -> 0 | X23: =IF(AND($I23>=$Y$12,$I23<=$Y$13),$I23,IF(AND($I23>=$Y$14,$I23<=$Y$15),$I23,0)) -> 0
A24: =A23+1 -> 44353 | B24: =VLOOKUP($A24,Datas!$B:$E,4,0) -> #N/A | C24: {=TEXT(INDEX($A$12:$A$41,MATCH(Datas!A14&Datas!C14&Datas!D14,Datas!$A$2:$A$336&Datas!$C$2:$C$336&Datas!$D$2:$D$336,0)),"DDD")} -> sáb | J24: =IFERROR((E24-D24)+(G24-F24)+(I24-H24)-#REF!,0) -> 0 | K24: 0.5 | L24: 0.29166667 | M24: 9 | R24: =S24+U24 -> 0 | S24: =IFERROR(T24-W24,0) -> 0 | T24: =IF(AND(D24>=$Y$14,D24<=$Y$15),$Y$15,IF(AND(D24>=$Y$12,D24<=$Y$13),$Y$12,0)) -> 0 | U24: =IFERROR(X24-V24,0) -> 0 | V24: =IF(AND(I24>=$Y$14,I24<=$Y$15),$Y$15,IF(AND(I24>=$Y$12,I24<=$Y$13),$Y$12,0)) -> 0 | W24: =IF(AND($D24>=$Y$12,$D24<=$Y$13),$D24,IF(AND($D24>=$Y$14,$D24<=$Y$15),$D24,0)) -> 0 | X24: =IF(AND($I24>=$Y$12,$I24<=$Y$13),$I24,IF(AND($I24>=$Y$14,$I24<=$Y$15),$I24,0)) -> 0
A25: =A24+1 -> 44354 | B25: =VLOOKUP($A25,Datas!$B:$E,4,0) -> #N/A | C25: {=TEXT(INDEX($A$12:$A$41,MATCH(Datas!A15&Datas!C15&Datas!D15,Datas!$A$2:$A$336&Datas!$C$2:$C$336&Datas!$D$2:$D$336,0)),"DDD")} -> dom | J25: =IFERROR((E25-D25)+(G25-F25)+(I25-H25)-#REF!,0) -> 0 | K25: 0.5 | L25: 0.29166667 | M25: 9 | R25: =S25+U25 -> 0 | S25: =IFERROR(T25-W25,0) -> 0 | T25: =IF(AND(D25>=$Y$14,D25<=$Y$15),$Y$15,IF(AND(D25>=$Y$12,D25<=$Y$13),$Y$12,0)) -> 0 | U25: =IFERROR(X25-V25,0) -> 0 | V25: =IF(AND(I25>=$Y$14,I25<=$Y$15),$Y$15,IF(AND(I25>=$Y$12,I25<=$Y$13),$Y$12,0)) -> 0 | W25: =IF(AND($D25>=$Y$12,$D25<=$Y$13),$D25,IF(AND($D25>=$Y$14,$D25<=$Y$15),$D25,0)) -> 0 | X25: =IF(AND($I25>=$Y$12,$I25<=$Y$13),$I25,IF(AND($I25>=$Y$14,$I25<=$Y$15),$I25,0)) -> 0
A26: =A25+1 -> 44355 | B26: =VLOOKUP($A26,Datas!$B:$E,4,0) -> #N/A | C26: {=TEXT(INDEX($A$12:$A$41,MATCH(Datas!A16&Datas!C16&Datas!D16,Datas!$A$2:$A$336&Datas!$C$2:$C$336&Datas!$D$2:$D$336,0)),"DDD")} -> seg | J26: =IFERROR((E26-D26)+(G26-F26)+(I26-H26)-#REF!,0) -> 0 | K26: 0 | L26: =R26 -> 0 | M26: =IF(J26>=0.01,9,0) -> 0 | R26: =S26+U26 -> 0 | S26: =IFERROR(T26-W26,0) -> 0 | T26: =IF(AND(D26>=$Y$14,D26<=$Y$15),$Y$15,IF(AND(D26>=$Y$12,D26<=$Y$13),$Y$12,0)) -> 0 | U26: =IFERROR(X26-V26,0) -> 0 | V26: =IF(AND(I26>=$Y$14,I26<=$Y$15),$Y$15,IF(AND(I26>=$Y$12,I26<=$Y$13),$Y$12,0)) -> 0 | W26: =IF(AND($D26>=$Y$12,$D26<=$Y$13),$D26,IF(AND($D26>=$Y$14,$D26<=$Y$15),$D26,0)) -> 0 | X26: =IF(AND($I26>=$Y$12,$I26<=$Y$13),$I26,IF(AND($I26>=$Y$14,$I26<=$Y$15),$I26,0)) -> 0
A27: =A26+1 -> 44356 | B27: =VLOOKUP($A27,Datas!$B:$E,4,0) -> #N/A | C27: {=TEXT(INDEX($A$12:$A$41,MATCH(Datas!A17&Datas!C17&Datas!D17,Datas!$A$2:$A$336&Datas!$C$2:$C$336&Datas!$D$2:$D$336,0)),"DDD")} -> ter | J27: =IFERROR((E27-D27)+(G27-F27)+(I27-H27)-#REF!,0) -> 0 | K27: 0.29166667 | L27: 0.25 | M27: 9 | R27: =S27+U27 -> 0 | S27: =IFERROR(T27-W27,0) -> 0 | T27: =IF(AND(D27>=$Y$14,D27<=$Y$15),$Y$15,IF(AND(D27>=$Y$12,D27<=$Y$13),$Y$12,0)) -> 0 | U27: =IFERROR(X27-V27,0) -> 0 | V27: =IF(AND(I27>=$Y$14,I27<=$Y$15),$Y$15,IF(AND(I27>=$Y$12,I27<=$Y$13),$Y$12,0)) -> 0 | W27: =IF(AND($D27>=$Y$12,$D27<=$Y$13),$D27,IF(AND($D27>=$Y$14,$D27<=$Y$15),$D27,0)) -> 0 | X27: =IF(AND($I27>=$Y$12,$I27<=$Y$13),$I27,IF(AND($I27>=$Y$14,$I27<=$Y$15),$I27,0)) -> 0
A28: =A27+1 -> 44357 | B28: =VLOOKUP($A28,Datas!$B:$E,4,0) -> #N/A | C28: {=TEXT(INDEX($A$12:$A$41,MATCH(Datas!A18&Datas!C18&Datas!D18,Datas!$A$2:$A$336&Datas!$C$2:$C$336&Datas!$D$2:$D$336,0)),"DDD")} -> qua | J28: =IFERROR((E28-D28)+(G28-F28)+(I28-H28)-#REF!,0) -> 0 | K28: 0.5 | L28: 0.29166667 | M28: 9 | R28: =S28+U28 -> 0 | S28: =IFERROR(T28-W28,0) -> 0 | T28: =IF(AND(D28>=$Y$14,D28<=$Y$15),$Y$15,IF(AND(D28>=$Y$12,D28<=$Y$13),$Y$12,0)) -> 0 | U28: =IFERROR(X28-V28,0) -> 0 | V28: =IF(AND(I28>=$Y$14,I28<=$Y$15),$Y$15,IF(AND(I28>=$Y$12,I28<=$Y$13),$Y$12,0)) -> 0 | W28: =IF(AND($D28>=$Y$12,$D28<=$Y$13),$D28,IF(AND($D28>=$Y$14,$D28<=$Y$15),$D28,0)) -> 0 | X28: =IF(AND($I28>=$Y$12,$I28<=$Y$13),$I28,IF(AND($I28>=$Y$14,$I28<=$Y$15),$I28,0)) -> 0
A29: =A28+1 -> 44358 | B29: =VLOOKUP($A29,Datas!$B:$E,4,0) -> #N/A | C29: {=TEXT(INDEX($A$12:$A$41,MATCH(Datas!A19&Datas!C19&Datas!D19,Datas!$A$2:$A$336&Datas!$C$2:$C$336&Datas!$D$2:$D$336,0)),"DDD")} -> qui | J29: =IFERROR((E29-D29)+(G29-F29)+(I29-H29)-#REF!,0) -> 0 | K29: 0.5 | L29: 0.29166667 | M29: 9 | R29: =S29+U29 -> 0 | S29: =IFERROR(T29-W29,0) -> 0 | T29: =IF(AND(D29>=$Y$14,D29<=$Y$15),$Y$15,IF(AND(D29>=$Y$12,D29<=$Y$13),$Y$12,0)) -> 0 | U29: =IFERROR(X29-V29,0) -> 0 | V29: =IF(AND(I29>=$Y$14,I29<=$Y$15),$Y$15,IF(AND(I29>=$Y$12,I29<=$Y$13),$Y$12,0)) -> 0 | W29: =IF(AND($D29>=$Y$12,$D29<=$Y$13),$D29,IF(AND($D29>=$Y$14,$D29<=$Y$15),$D29,0)) -> 0 | X29: =IF(AND($I29>=$Y$12,$I29<=$Y$13),$I29,IF(AND($I29>=$Y$14,$I29<=$Y$15),$I29,0)) -> 0
A30: =A29+1 -> 44359 | B30: =VLOOKUP($A30,Datas!$B:$E,4,0) -> #N/A | C30: {=TEXT(INDEX($A$12:$A$41,MATCH(Datas!A20&Datas!C20&Datas!D20,Datas!$A$2:$A$336&Datas!$C$2:$C$336&Datas!$D$2:$D$336,0)),"DDD")} -> sex | J30: =IFERROR((E30-D30)+(G30-F30)+(I30-H30)-#REF!,0) -> 0 | K30: 0.5 | L30: 0.29166667 | M30: 9 | R30: =S30+U30 -> 0 | S30: =IFERROR(T30-W30,0) -> 0 | T30: =IF(AND(D30>=$Y$14,D30<=$Y$15),$Y$15,IF(AND(D30>=$Y$12,D30<=$Y$13),$Y$12,0)) -> 0 | U30: =IFERROR(X30-V30,0) -> 0 | V30: =IF(AND(I30>=$Y$14,I30<=$Y$15),$Y$15,IF(AND(I30>=$Y$12,I30<=$Y$13),$Y$12,0)) -> 0 | W30: =IF(AND($D30>=$Y$12,$D30<=$Y$13),$D30,IF(AND($D30>=$Y$14,$D30<=$Y$15),$D30,0)) -> 0 | X30: =IF(AND($I30>=$Y$12,$I30<=$Y$13),$I30,IF(AND($I30>=$Y$14,$I30<=$Y$15),$I30,0)) -> 0
A31: =A30+1 -> 44360 | B31: =VLOOKUP($A31,Datas!$B:$E,4,0) -> #N/A | C31: {=TEXT(INDEX($A$12:$A$41,MATCH(Datas!A21&Datas!C21&Datas!D21,Datas!$A$2:$A$336&Datas!$C$2:$C$336&Datas!$D$2:$D$336,0)),"DDD")} -> sáb | J31: =IFERROR((E31-D31)+(G31-F31)+(I31-H31)-#REF!,0) -> 0 | K31: 0.5 | L31: 0.29166667 | M31: 9 | R31: =S31+U31 -> 0 | S31: =IFERROR(T31-W31,0) -> 0 | T31: =IF(AND(D31>=$Y$14,D31<=$Y$15),$Y$15,IF(AND(D31>=$Y$12,D31<=$Y$13),$Y$12,0)) -> 0 | U31: =IFERROR(X31-V31,0) -> 0 | V31: =IF(AND(I31>=$Y$14,I31<=$Y$15),$Y$15,IF(AND(I31>=$Y$12,I31<=$Y$13),$Y$12,0)) -> 0 | W31: =IF(AND($D31>=$Y$12,$D31<=$Y$13),$D31,IF(AND($D31>=$Y$14,$D31<=$Y$15),$D31,0)) -> 0 | X31: =IF(AND($I31>=$Y$12,$I31<=$Y$13),$I31,IF(AND($I31>=$Y$14,$I31<=$Y$15),$I31,0)) -> 0
A32: =A31+1 -> 44361 | B32: =VLOOKUP($A32,Datas!$B:$E,4,0) -> #N/A | C32: {=TEXT(INDEX($A$12:$A$41,MATCH(Datas!A22&Datas!C22&Datas!D22,Datas!$A$2:$A$336&Datas!$C$2:$C$336&Datas!$D$2:$D$336,0)),"DDD")} -> dom | J32: =IFERROR((E32-D32)+(G32-F32)+(I32-H32)-#REF!,0) -> 0 | K32: 0.5 | L32: 0.29166667 | M32: 9 | R32: =S32+U32 -> 0 | S32: =IFERROR(T32-W32,0) -> 0 | T32: =IF(AND(D32>=$Y$14,D32<=$Y$15),$Y$15,IF(AND(D32>=$Y$12,D32<=$Y$13),$Y$12,0)) -> 0 | U32: =IFERROR(X32-V32,0) -> 0 | V32: =IF(AND(I32>=$Y$14,I32<=$Y$15),$Y$15,IF(AND(I32>=$Y$12,I32<=$Y$13),$Y$12,0)) -> 0 | W32: =IF(AND($D32>=$Y$12,$D32<=$Y$13),$D32,IF(AND($D32>=$Y$14,$D32<=$Y$15),$D32,0)) -> 0 | X32: =IF(AND($I32>=$Y$12,$I32<=$Y$13),$I32,IF(AND($I32>=$Y$14,$I32<=$Y$15),$I32,0)) -> 0
